Workbook

Sheet SO SKUs
A1: Special Order SKUs: Cleaned & Categorized
A2: Cleaned descriptions and suggested short descriptions (30 char max). Notes shaded by fix priority: pink high, orange medium, green low (see ERP Fixes tab). Gray rows = Stocked FALSE.
A4: Category | B4: Product Code | C4: Description | D4: Short Description | E4: UOM | F4: Stocked | G4: Cleanup Notes
A5: Windows | B5: SO ATRIUM | C5: SPECIAL ORDER ATRIUM WINDOW | D5: SPECIAL ORDER ATRIUM WINDOW | E5: ea | F5: =TRUE() -> TRUE
A6: Windows | B6: SO ES WINDOWS | C6: SPECIAL ORDER ES WINDOW | D6: SPECIAL ORDER ES WINDOW | E6: ea | F6: =TRUE() -> TRUE | G6: Code is plural, every other window code is singular
A7: Windows | B7: SO JELD-WEN | C7: SPECIAL ORDER JELD-WEN WINDOW | D7: SPECIAL ORDER JELD-WEN WINDOW | E7: ea | F7: =TRUE() -> TRUE | G7: Short desc was SPECIAL ORDER JELD-WEN
A8: Windows | B8: SO KOLBE | C8: SPECIAL ORDER KOLBE WINDOW | D8: SPECIAL ORDER KOLBE WINDOW | E8: ea | F8: =TRUE() -> TRUE | G8: Short desc was generic SPECIAL ORDER WINDOW
A9: Windows | B9: SO LEPAGE | C9: SPECIAL ORDER LEPAGE WINDOW | D9: SPECIAL ORDER LEPAGE WINDOW | E9: ea | F9: =TRUE() -> TRUE | G9: Code had a leading space; description reworded to match (was WINDOW SPECIAL ORDER LEPAGE); short desc was generic; Avg Cost UOM blank
A10: Windows | B10: SO MISC WOOD WINDOW | C10: SPECIAL ORDER MISC WOOD WINDOW | D10: SPECIAL ORDER MISC WOOD WINDOW | E10: ea | F10: =TRUE() -> TRUE
A11: Windows | B11: SO PGT | C11: SPECIAL ORDER PGT WINDOW | D11: SPECIAL ORDER PGT WINDOW | E11: ea | F11: =TRUE() -> TRUE | G11: Short desc was generic SPECIAL ORDER WINDOW
A12: Windows | B12: SO PLYGEM | C12: SPECIAL ORDER PLYGEM WINDOW | D12: SPECIAL ORDER PLYGEM WINDOW | E12: ea | F12: =TRUE() -> TRUE | G12: Short desc was SPECIAL ORDER PLYGEM; Avg Cost UOM blank
A13: Windows | B13: SO QUAKER | C13: SPECIAL ORDER QUAKER WINDOW | D13: SPECIAL ORDER QUAKER WINDOW | E13: ea | F13: =TRUE() -> TRUE | G13: Description had a leading space; short desc was generic; Avg Cost UOM blank
A14: Windows | B14: SO QUARTZ | C14: SPECIAL ORDER QUARTZ WINDOW | D14: SPECIAL ORDER QUARTZ WINDOW | E14: ea | F14: =TRUE() -> TRUE | G14: Description had leading spaces; short desc was generic; Avg Cost UOM blank
A15: Windows | B15: SO SIMONTON | C15: SPECIAL ORDER SIMONTON WINDOW | D15: SPECIAL ORDER SIMONTON WINDOW | E15: ea | F15: =TRUE() -> TRUE
A16: Windows | B16: SO WINDSOR | C16: SPECIAL ORDER WINDSOR WINDOW | D16: SPECIAL ORDER WINDSOR WINDOW | E16: ea | F16: =TRUE() -> TRUE | G16: Short desc was SPECIAL ORDER WINDSOR
A17: Windows | B17: SO YKK | C17: SPECIAL ORDER YKK WINDOW | D17: SPECIAL ORDER YKK WINDOW | E17: ea | F17: =TRUE() -> TRUE
A18: Windows | B18: SO WINDOW PARTS | C18: SPECIAL ORDER WINDOW PARTS | D18: SPECIAL ORDER WINDOW PARTS | E18: ea | F18: =TRUE() -> TRUE | G18: Short desc was WRONG (said SPECIAL ORDER WINDSOR)
A19: Windows | B19: SO COMMERCIAL JELD-WEN WINDOW | C19: SPECIAL ORDER COMMERCIAL JELD-WEN WINDOW | D19: SPECIAL ORDER COM JELD-WEN | E19: ea | F19: =TRUE() -> TRUE | G19: Description reworded (was WINDOW SPECIAL ORDER COMMERCIAL JELD-WEN); short desc was generic
A20: Windows | B20: SO COMMERCIAL PGT WINDOW | C20: SPECIAL ORDER COMMERCIAL PGT WINDOW | D20: SPECIAL ORDER COM PGT WINDOW | E20: ea | F20: =TRUE() -> TRUE | G20: Short desc was generic SPECIAL ORDER WINDOW
A21: Windows | B21: SO COMMERCIAL MISC WINDOW | C21: SPECIAL ORDER COMMERCIAL MISC WINDOW | D21: SPECIAL ORDER COM MISC WINDOW | E21: ea | F21: =TRUE() -> TRUE | G21: Short desc was generic SPECIAL ORDER WINDOW
A22: Windows | B22: SO COMMERCIAL WINDOW PARTS | C22: SPECIAL ORDER COMMERCIAL WINDOW PARTS | D22: SPECIAL ORDER COM WINDOW PARTS | E22: ea | F22: =TRUE() -> TRUE
A23: Doors | B23: SO INT DOOR | C23: SPECIAL ORDER INTERIOR DOOR | D23: SPECIAL ORDER INTERIOR DOOR | E23: ea | F23: =TRUE() -> TRUE | G23: Keep: use this one for interior doors
A24: Doors | B24: SO INTERIOR DOOR | C24: SPECIAL ORDER INTERIOR DOOR | D24: SPECIAL ORDER INTERIOR DOOR | E24: ea | F24: =FALSE() -> FALSE | G24: DUPLICATE of SO INT DOOR; consider retiring; Avg Cost UOM blank
A25: Doors | B25: SO COMMERCIAL INT DOOR | C25: SPECIAL ORDER COMMERCIAL INTERIOR DOOR | D25: SPECIAL ORDER COM INT DOOR | E25: ea | F25: =TRUE() -> TRUE | G25: Description reworded (was INTERIOR DOOR SPECIAL ORDER COMMERCIAL); short desc was same as residential SO INT DOOR
A26: Doors | B26: SO EXT DOOR | C26: SPECIAL ORDER EXTERIOR DOOR | D26: SPECIAL ORDER EXTERIOR DOOR | E26: ea | F26: =TRUE() -> TRUE | G26: Keep: use this one for general exterior doors
A27: Doors | B27: SO EXTERIOR DOOR | C27: SPECIAL ORDER EXTERIOR DOOR | D27: SPECIAL ORDER EXTERIOR DOOR | E27: ea | F27: =FALSE() -> FALSE | G27: DUPLICATE of SO EXT DOOR; consider retiring; description was plural DOORS
A28: Doors | B28: SO EXT FIBERGLASS DOOR | C28: SPECIAL ORDER EXTERIOR FIBERGLASS DOOR | D28: SPECIAL ORDER FIBERGLASS DOOR | E28: ea | F28: =TRUE() -> TRUE | G28: Short desc had a double space
A29: Doors | B29: SO EXT STEEL DOOR | C29: SPECIAL ORDER EXTERIOR STEEL DOOR | D29: SPECIAL ORDER EXT STEEL DOOR | E29: ea | F29: =TRUE() -> TRUE
A30: Doors | B30: SO EXT WOOD DOOR | C30: SPECIAL ORDER EXTERIOR WOOD DOOR | D30: SPECIAL ORDER EXT WOOD DOOR | E30: ea | F30: =TRUE() -> TRUE
A31: Doors | B31: SO EXT ORIGIN DOOR | C31: SPECIAL ORDER EXTERIOR ORIGIN DOOR | D31: SPECIAL ORDER ORIGIN DOOR | E31: ea | F31: =TRUE() -> TRUE | G31: Added EXTERIOR to description to match the other EXT codes
A32: Doors | B32: SO EXT MISC MULTI SLIDE DOOR | C32: SPECIAL ORDER EXTERIOR MISC MULTI SLIDE DOOR | D32: SPECIAL ORDER EXT MULTI SLIDE | E32: ea | F32: =TRUE() -> TRUE | G32: Short desc had a double space
A33: Doors | B33: SO COMMERCIAL EXT DOOR | C33: SPECIAL ORDER COMMERCIAL EXTERIOR DOOR | D33: SPECIAL ORDER COM EXT DOOR | E33: ea | F33: =TRUE() -> TRUE | G33: Description reworded (was EXTERIOR DOOR SPECIAL ORDER COMMERCIAL); short desc had a double space
A34: Doors | B34: SO DOOR HARDWARE | C34: SPECIAL ORDER DOOR HARDWARE | D34: SPECIAL ORDER DOOR HARDWARE | E34: ea | F34: =FALSE() -> FALSE
A35: Millwork | B35: SO MILLWORK (EACH) | C35: SPECIAL ORDER MILLWORK (EACH) | D35: SPECIAL ORDER MILLWORK (EACH) | E35: ea | F35: =TRUE() -> TRUE
A36: Millwork | B36: SO MILLWORK (LF) | C36: SPECIAL ORDER MILLWORK (LF) | D36: SPECIAL ORDER MILLWORK (LF) | E36: LF-1 | F36: =TRUE() -> TRUE
A37: Millwork | B37: SO MILLWORK (BF) | C37: SPECIAL ORDER MILLWORK (BF) | D37: SPECIAL ORDER MILLWORK (BF) | E37: BF-1 | F37: =TRUE() -> TRUE | G37: Short desc was WRONG (said MILLWORK (LF))
A38: Millwork | B38: SO AW MILLWORK (EACH) | C38: SPECIAL ORDER AW MILLWORK (EACH) | D38: SPECIAL ORDER AW MILLWORK (EA) | E38: ea | F38: =FALSE() -> FALSE | G38: Description had a double space; short desc was identical to SO MILLWORK (EACH); Avg Cost UOM blank
A39: Millwork | B39: SO MOULDER (LF) | C39: SPECIAL ORDER MOULDER (LF) | D39: SPECIAL ORDER MOULDER (LF) | E39: LF-1 | F39: =FALSE() -> FALSE
A40: Millwork | B40: SO S4S | C40: SPECIAL ORDER S4S | D40: SPECIAL ORDER S4S | E40: LF-1 | F40: =FALSE() -> FALSE
A41: Millwork | B41: SO PVC | C41: SPECIAL ORDER PVC | D41: SPECIAL ORDER PVC | E41: ea | F41: =FALSE() -> FALSE
...

Sheet ERP Fixes
A1: ERP Cleanup To-Do
A2: Put an X in the yellow Done column as each record is fixed. High = duplicates, wrong descriptions, bad codes.
A4: Category | B4: Product Code | C4: Priority | D4: Issue | E4: Suggested Description | F4: Suggested Short Description | G4: Done
A5: Windows | B5: SO LEPAGE | C5: High | D5: Code had a leading space; description reworded to match (was WINDOW SPECIAL ORDER LEPAGE); short desc was generic; Avg Cost UOM blank | E5: SPECIAL ORDER LEPAGE WINDOW | F5: SPECIAL ORDER LEPAGE WINDOW
A6: Windows | B6: SO WINDOW PARTS | C6: High | D6: Short desc was WRONG (said SPECIAL ORDER WINDSOR) | E6: SPECIAL ORDER WINDOW PARTS | F6: SPECIAL ORDER WINDOW PARTS
A7: Doors | B7: SO INTERIOR DOOR | C7: High | D7: DUPLICATE of SO INT DOOR; consider retiring; Avg Cost UOM blank | E7: SPECIAL ORDER INTERIOR DOOR | F7: SPECIAL ORDER INTERIOR DOOR
A8: Doors | B8: SO EXTERIOR DOOR | C8: High | D8: DUPLICATE of SO EXT DOOR; consider retiring; description was plural DOORS | E8: SPECIAL ORDER EXTERIOR DOOR | F8: SPECIAL ORDER EXTERIOR DOOR
A9: Millwork | B9: SO MILLWORK (BF) | C9: High | D9: Short desc was WRONG (said MILLWORK (LF)) | E9: SPECIAL ORDER MILLWORK (BF) | F9: SPECIAL ORDER MILLWORK (BF)
A10: Lumber & Panels | B10: SO LUMBER-PC | C10: High | D10: Code had trailing spaces; short desc was WRONG (said SPECIAL ORDER SHINGLES) | E10: SPECIAL ORDER LUMBER-PC | F10: SPECIAL ORDER LUMBER-PC
A11: Roofing | B11: SO ROOF SHAKE-PC | C11: High | D11: Code and description had a leading space; short desc was same as non-PC | E11: SPECIAL ORDER ROOF SHAKE-PC | F11: SPECIAL ORDER ROOF SHAKE-PC
A12: Millwork | B12: SO PRIMER (LF) | C12: Medium | D12: Name says LF but sells by ea; has a price set (sell 0.52 / buy 0.35) | E12: SPECIAL ORDER PRIMER (LF) | F12: SPECIAL ORDER PRIMER (LF)
A13: Millwork | B13: SO MANTIS | C13: Medium | D13: Has a price set (sell 0.50 / buy 0.34); check if it should be per LF | E13: SPECIAL ORDER MANTIS CNC | F13: SPECIAL ORDER MANTIS CNC
A14: Misc | B14: SO MISC | C14: Medium | D14: Has a stray Last Cost of 0.56 | E14: SPECIAL ORDER MISC ITEMS | F14: SPECIAL ORDER MISC ITEMS
A15: Windows | B15: SO ES WINDOWS | C15: Low | D15: Code is plural, every other window code is singular | E15: SPECIAL ORDER ES WINDOW | F15: SPECIAL ORDER ES WINDOW
A16: Windows | B16: SO JELD-WEN | C16: Low | D16: Short desc was SPECIAL ORDER JELD-WEN | E16: SPECIAL ORDER JELD-WEN WINDOW | F16: SPECIAL ORDER JELD-WEN WINDOW
... A35: Roofing | B35: SO ROOF SHAKE | C35: Low | D35: Avg Cost UOM blank | E35: SPECIAL ORDER ROOF SHAKE | F35: SPECIAL ORDER ROOF SHAKE

Sheet Summary
A1: Summary
A2: Counts update automatically from the other two tabs.
A4: Category | B4: SKUs | C4: Stocked TRUE | D4: Stocked FALSE | E4: ERP Fixes | F4: Fixes Done | G4: Fixes Left
A5: Windows | B5: =COUNTIF('SO SKUs'!$A$5:$A$61,A5) -> 18 | C5: =COUNTIFS('SO SKUs'!$A$5:$A$61,A5,'SO SKUs'!$F$5:$F$61,TRUE()) -> 18 | D5: =COUNTIFS('SO SKUs'!$A$5:$A$61,A5,'SO SKUs'!$F$5:$F$61,FALSE()) -> 0 | E5: =COUNTIF('ERP Fixes'!$A$5:$A$35,A5) -> 13 | F5: =COUNTIFS('ERP Fixes'!$A$5:$A$35,A5,'ERP Fixes'!$G$5:$G$35,"X") -> 0 | G5: =E5-F5 -> 13
A6: Doors | B6: =COUNTIF('SO SKUs'!$A$5:$A$61,A6) -> 12 | C6: =COUNTIFS('SO SKUs'!$A$5:$A$61,A6,'SO SKUs'!$F$5:$F$61,TRUE()) -> 9 | D6: =COUNTIFS('SO SKUs'!$A$5:$A$61,A6,'SO SKUs'!$F$5:$F$61,FALSE()) -> 3 | E6: =COUNTIF('ERP Fixes'!$A$5:$A$35,A6) -> 7 | F6: =COUNTIFS('ERP Fixes'!$A$5:$A$35,A6,'ERP Fixes'!$G$5:$G$35,"X") -> 0 | G6: =E6-F6 -> 7
A7: Millwork | B7: =COUNTIF('SO SKUs'!$A$5:$A$61,A7) -> 10 | C7: =COUNTIFS('SO SKUs'!$A$5:$A$61,A7,'SO SKUs'!$F$5:$F$61,TRUE()) -> 4 | D7: =COUNTIFS('SO SKUs'!$A$5:$A$61,A7,'SO SKUs'!$F$5:$F$61,FALSE()) -> 6 | E7: =COUNTIF('ERP Fixes'!$A$5:$A$35,A7) -> 5 | F7: =COUNTIFS('ERP Fixes'!$A$5:$A$35,A7,'ERP Fixes'!$G$5:$G$35,"X") -> 0 | G7: =E7-F7 -> 5
A8: Lumber & Panels | B8: =COUNTIF('SO SKUs'!$A$5:$A$61,A8) -> 8 | C8: =COUNTIFS('SO SKUs'!$A$5:$A$61,A8,'SO SKUs'!$F$5:$F$61,TRUE()) -> 1 | D8: =COUNTIFS('SO SKUs'!$A$5:$A$61,A8,'SO SKUs'!$F$5:$F$61,FALSE()) -> 7 | E8: =COUNTIF('ERP Fixes'!$A$5:$A$35,A8) -> 1 | F8: =COUNTIFS('ERP Fixes'!$A$5:$A$35,A8,'ERP Fixes'!$G$5:$G$35,"X") -> 0 | G8: =E8-F8 -> 1
A9: Structural | B9: =COUNTIF('SO SKUs'!$A$5:$A$61,A9) -> 3 | C9: =COUNTIFS('SO SKUs'!$A$5:$A$61,A9,'SO SKUs'!$F$5:$F$61,TRUE()) -> 2 | D9: =COUNTIFS('SO SKUs'!$A$5:$A$61,A9,'SO SKUs'!$F$5:$F$61,FALSE()) -> 1 | E9: =COUNTIF('ERP Fixes'!$A$5:$A$35,A9) -> 0 | F9: =COUNTIFS('ERP Fixes'!$A$5:$A$35,A9,'ERP Fixes'!$G$5:$G$35,"X") -> 0 | G9: =E9-F9 -> 0
A10: Roofing | B10: =COUNTIF('SO SKUs'!$A$5:$A$61,A10) -> 4 | C10: =COUNTIFS('SO SKUs'!$A$5:$A$61,A10,'SO SKUs'!$F$5:$F$61,TRUE()) -> 4 | D10: =COUNTIFS('SO SKUs'!$A$5:$A$61,A10,'SO SKUs'!$F$5:$F$61,FALSE()) -> 0 | E10: =COUNTIF('ERP Fixes'!$A$5:$A$35,A10) -> 4 | F10: =COUNTIFS('ERP Fixes'!$A$5:$A$35,A10,'ERP Fixes'!$G$5:$G$35,"X") -> 0 | G10: =E10-F10 -> 4
A11: Misc | B11: =COUNTIF('SO SKUs'!$A$5:$A$61,A11) -> 2 | C11: =COUNTIFS('SO SKUs'!$A$5:$A$61,A11,'SO SKUs'!$F$5:$F$61,TRUE()) -> 1 | D11: =COUNTIFS('SO SKUs'!$A$5:$A$61,A11,'SO SKUs'!$F$5:$F$61,FALSE()) -> 1 | E11: =COUNTIF('ERP Fixes'!$A$5:$A$35,A11) -> 1 | F11: =COUNTIFS('ERP Fixes'!$A$5:$A$35,A11,'ERP Fixes'!$G$5:$G$35,"X") -> 0 | G11: =E11-F11 -> 1
A12: Total | B12: =SUM(B5:B11) -> 57 | C12: =SUM(C5:C11) -> 39 | D12: =SUM(D5:D11) -> 18 | E12: =SUM(E5:E11) -> 31 | F12: =SUM(F5:F11) -> 0 | G12: =SUM(G5:G11) -> 31
