Workbook

Sheet Instructions
B1: FOUR CORNERS COMMERCIAL QUOTE TEMPLATE
B2: For multifamily and commercial Div 6 / 8 / 10 bids (trim, doors, frames, hardware, specialties). Built from the Carter Lumber proposal format GCs already know.
B4: HOW TO USE
B5: 1. Save As | C5: Save a copy per job: [Job Name] - [GC] - Proposal [#].xlsx. Never type in the master template.
B6: 2. Job Info | C6: Fill every yellow cell: GC, job, plans date, estimator, tax rate (VERIFY the county), margins, bond, dates, and area names.
B7: 3. Line Detail | C7: One row per takeoff item. Pick a Bid Group (Base / Alt 1-5 / Optional / Excluded), CSI Section, Area, Qty, UOM, and enter COST. Sell price, tax, and extensions calculate. Red cells = missing required info.
C8: Per-line margin overrides go in the two 'Override' columns (blank = Job Info default). Delete the 4 blue-italic EXAMPLE rows first.
B9: 4. Alternates | C9: Describe each alternate. Amounts total automatically from Line Detail lines tagged Alt 1-5. Use negative quantities for deducts.
B10: 5. Scope Terms | C10: Set each inclusion, exclusion, qualification, and term to Yes/No for this job. Only 'Yes' items print, auto-numbered. Edit wording as needed.
B11: 6. Review | C11: Check the JOB MARGIN CHECK block at the bottom of Job Info: unassigned $ and missing Bid Group count must both be zero. Look at GP% and labor %.
B12: 7. Send | C12: Print to PDF: Proposal + Area Breakout + Bid Summary (in that order). NEVER send Line Detail or Job Info; they show cost and margin.
C13: Bid Summary's print area grows with the number of lines automatically in Excel. If it ever prints blank pages, select the filled rows and use Page Layout > Print Area > Set Print Area.
B14: 8. VE / Revisions | C14: Before re-pricing, copy the current section totals into 'Bid Comparison' prior columns, then make changes. The sheet shows the deltas for the GC.
B16: COLOR KEY
B17: Yellow + blue text | C17: Input - type here.
B18: Green text | C18: Pulls from another sheet - don't overwrite unless you mean to.
B19: Black text | C19: Formula - don't touch.
B20: Blue italic | C20: Example data - delete before use.
B22: SHEETS
B23: Proposal | C23: CUSTOMER. Cover letter, CSI summary, bond, base total, alternates, inclusions/exclusions/qualifications/terms, signature block.
B24: Area Breakout | C24: CUSTOMER. Section x area matrix plus material/labor by area (Carter's 'Apartments / Clubhouse / Pool Cabana' pages).
B25: Bid Summary | C25: CUSTOMER. Numbered line items with unit and extended price, compacted automatically (no blank rows, Excluded lines removed).
B26: Bid Comparison | C26: CUSTOMER (optional). VE or revision delta sheet.
B27: Line Detail | C27: INTERNAL. Takeoff with cost, margin, and sell.
B28: Job Info | C28: INTERNAL. Inputs and margin check.
B29: Scope Terms | C29: INTERNAL. Library of scope language.
B30: Alternates / Lists | C30: INTERNAL. Supporting tables. Add custom CSI sections in the yellow rows on Lists.
B32: BEFORE FIRST USE | C32: Have Wesley (company attorney) review the Terms & Conditions and Qualifications on 'Scope Terms', especially the finance charge, lien, warranty, and escalation language.

Sheet Job Info
A1: JOB INFO & PRICING INPUTS
A2: Yellow cells with blue text are inputs. Everything else calculates.
A4: COMPANY
A5: Company Name | B5: Four Corners Building Supply
A6: Address | B6: 4349 Corporate Road
A7: City / State / Zip | B7: North Charleston, SC 29405
A8: Office Phone | B8: (843) 970-3812
A9: Website | B9: www.buildfcbs.com
A11: CUSTOMER / GENERAL CONTRACTOR
A12: General Contractor
A13: Attention
A14: Address
A15: City / State / Zip
A16: Phone
A17: Email
A19: PROJECT
A20: Job Name
A21: Four Corners Job #
A22: Job Address
A23: Job City / State / Zip
A24: Project Type | B24: Multifamily
A25: Plans / Specs Dated | C25: Leave blank to print '[date TBD]'.
A26: Addenda Acknowledged | B26: None
A27: Proposal Date
A28: Proposal # | C28: Suggest: FC-YYMM-### (e.g. FC-2610-001).
A29: Revision | B29: 0
A31: ESTIMATOR
A32: Estimator Name
A33: Estimator Phone
A34: Estimator Email
A36: PRICING & COMMERCIAL TERMS
A37: Sales Tax Rate on Material | B37: 0.09 | C37: 9% = Charleston/Berkeley Co. (Carter used 9% on Goose Creek, 7% on Bluffton). VERIFY the county rate for every job.
A38: Include Tax in Material Prices? | B38: Yes
A39: Default Material Margin (GP %) | B39: 0.2 | C39: Gross margin: sell = cost / (1 - margin). Can be overridden per line on Line Detail.
A40: Default Labor Margin (GP %) | B40: 0.15 | C40: Gross margin on installer cost. Can be overridden per line on Line Detail.
A41: Payment & Performance Bond Required? | B41: No
A42: Bond Rate (% of base bid) | B42: 0.015 | C42: 1.5% matches the bond Carter carried on Pepper Hall ($36,008 on ~$2.40M). Get a real quote from the surety on bonded jobs.
A43: Proposal Valid (days) | B43: 30 | C43: Carter used 30 days.
A44: Escalation Threshold Before Pass-Through | B44: 0.03 | C44: Material increases above this % get passed to the GC (Qualification #3).
A45: Contract & Approved Submittals By
...

Sheet Line Detail
A1: LINE DETAIL / TAKEOFF (INTERNAL - contains cost)
A2: ="Job: "&IF('Job Info'!$B$20="","[Job Name]",'Job Info'!$B$20)&" | Tax on material: "&IF('Job Info'!$B$38="Yes",TEXT('Job Info'!$B$37,"0.00%"),"not included")&" | Default margins: Mat "&TEXT('Job Info'!$B$39,"0.0%")&" / Labor "&TEXT('Job Info'!$B$40,"0.0%") -> Job: [Job Name] | Tax on material: 9.00% | Default margins: Mat 20.0% / Labor 15.0%
A3: Enter lines grouped by CSI section, then by area, so the Bid Summary prints in a sensible order. Put each hardware set's components in the Description (one line per set, like Carter does).
A4: WHAT | I4: COST INPUTS | M4: SELL (calculated) | S4: NOTES | U4: HELPERS
A5: Line # | B5: Bid Group | C5: CSI Section | D5: Area | E5: Mark / Tag | F5: Description / Specification | G5: Qty | H5: UOM | I5: Mat Unit Cost | J5: Labor Unit Cost | K5: Mat Margin Override | L5: Labor Margin Override | M5: Mat Unit Sell (incl. tax) | N5: Labor Unit Sell | O5: Unit Price (Mat + Labor) | P5: Material Ext. | Q5: Labor Ext. | R5: Total Ext. | S5: Customer Note (prints) | T5: Internal Note (does not print) | U5: Mat Cost Ext. | V5: Labor Cost Ext. | W5: Print Seq | X5: Tax $
A6: =IF(F6="","",ROW()-5) -> 1 | B6: Base | C6: 06 20 00 Interior Trim / Finish Carpentry | D6: Units / Apartments | F6: Base FJ Primed 1x6 | G6: 1000 | H6: LF | I6: 1.45 | J6: 1.1 | M6: =IF(F6="","",N(I6)/(1-IF(K6="",'Job Info'!$B$39,K6))*(1+IF('Job Info'!$B$38="Yes",'Job Info'!$B$37,0))) -> 1.975625 | N6: =IF(F6="","",N(J6)/(1-IF(L6="",'Job Info'!$B$40,L6))) -> 1.2941176 | O6: =IF(F6="","",M6+N6) -> 3.2697426 | P6: =IF(F6="","",N(G6)*M6) -> 1975.625 | Q6: =IF(F6="","",N(G6)*N6) -> 1294.1176 | R6: =IF(F6="","",P6+Q6) -> 3269.7426 | T6: EXAMPLE - delete before use | U6: =IF(F6="","",N(G6)*N(I6)) -> 1450 | V6: =IF(F6="","",N(G6)*N(J6)) -> 1100 | W6: =IF(F6="","",IF(B6="Excluded","",COUNTIFS($F$6:F6,"?*",$B$6:B6,"<>Excluded"))) -> 1 | X6: =IF(F6="","",N(G6)*N(I6)/(1-IF(K6="",'Job Info'!$B$39,K6))*IF('Job Info'!$B$38="Yes",'Job Info'!$B$37,0)) -> 163.125
A7: =IF(F7="","",ROW()-5) -> 2 | B7: Base | C7: 08 17 43 Interior Pre-Hung Doors | D7: Units / Apartments | E7: Type 4 | F7: 3068 Hollow Core Hardboard 2-Panel Shaker 1-3/8", FJ split jamb 4-7/8" w/ FJ 1x4 casing, 3 ea US15 hinges, 2-3/8" backset single bore | G7: 10 | H7: EA | I7: 165 | J7: 38 | M7: =IF(F7="","",N(I7)/(1-IF(K7="",'Job Info'!$B$39,K7))*(1+IF('Job Info'!$B$38="Yes",'Job Info'!$B$37,0))) -> 224.8125 | N7: =IF(F7="","",N(J7)/(1-IF(L7="",'Job Info'!$B$40,L7))) -> 44.705882 | O7: =IF(F7="","",M7+N7) -> 269.51838 | P7: =IF(F7="","",N(G7)*M7) -> 2248.125 | Q7: =IF(F7="","",N(G7)*N7) -> 447.05882 | R7: =IF(F7="","",P7+Q7) -> 2695.1838 | T7: EXAMPLE - delete before use | U7: =IF(F7="","",N(G7)*N(I7)) -> 1650 | V7: =IF(F7="","",N(G7)*N(J7)) -> 380 | W7: =IF(F7="","",IF(B7="Excluded","",COUNTIFS($F$6:F7,"?*",$B$6:B7,"<>Excluded"))) -> 2 | X7: =IF(F7="","",N(G7)*N(I7)/(1-IF(K7="",'Job Info'!$B$39,K7))*IF('Job Info'!$B$38="Yes",'Job Info'!$B$37,0)) -> 185.625
A8: =IF(F8="","",ROW()-5) -> 3 | B8: Base | C8: 08 71 00 Door Hardware | D8: Units / Apartments | E8: HW Set Bed/Bath | F8: 1 ea privacy lever US15; 1 ea door stop US15 | G8: 10 | H8: SET | I8: 18.5 | J8: 9.5 | M8: =IF(F8="","",N(I8)/(1-IF(K8="",'Job Info'!$B$39,K8))*(1+IF('Job Info'!$B$38="Yes",'Job Info'!$B$37,0))) -> 25.20625 | N8: =IF(F8="","",N(J8)/(1-IF(L8="",'Job Info'!$B$40,L8))) -> 11.176471 | O8: =IF(F8="","",M8+N8) -> 36.382721 | P8: =IF(F8="","",N(G8)*M8) -> 252.0625 | Q8: =IF(F8="","",N(G8)*N8) -> 111.76471 | R8: =IF(F8="","",P8+Q8) -> 363.82721 | T8: EXAMPLE - delete before use | U8: =IF(F8="","",N(G8)*N(I8)) -> 185 | V8: =IF(F8="","",N(G8)*N(J8)) -> 95 | W8: =IF(F8="","",IF(B8="Excluded","",COUNTIFS($F$6:F8,"?*",$B$6:B8,"<>Excluded"))) -> 3 | X8: =IF(F8="","",N(G8)*N(I8)/(1-IF(K8="",'Job Info'!$B$39,K8))*IF('Job Info'!$B$38="Yes",'Job Info'!$B$37,0)) -> 20.8125
A9: =IF(F9="","",ROW()-5) -> 4 | B9: Alt 1 | C9: 08 71 00 Door Hardware | D9: Units / Apartments | E9: HW Set Entry | F9: ADD: battery-powered keypad deadbolt in lieu of keyed deadbolt | G9: 10 | H9: EA | I9: 240 | J9: 25 | M9: =IF(F9="","",N(I9)/(1-IF(K9="",'Job Info'!$B$39,K9))*(1+IF('Job Info'!$B$38="Yes",'Job Info'!$B$37,0))) -> 327 | N9: =IF(F9="","",N(J9)/(1-IF(L9="",'Job Info'!$B$40,L9))) -> 29.411765 | O9: =IF(F9="","",M9+N9) -> 356.41176 | P9: =IF(F9="","",N(G9)*M9) -> 3270 | Q9: =IF(F9="","",N(G9)*N9) -> 294.11765 | R9: =IF(F9="","",P9+Q9) -> 3564.1176 | S9: Add alternate | T9: EXAMPLE - delete before use | U9: =IF(F9="","",N(G9)*N(I9)) -> 2400 | V9: =IF(F9="","",N(G9)*N(J9)) -> 250 | W9: =IF(F9="","",IF(B9="Excluded","",COUNTIFS($F$6:F9,"?*",$B$6:B9,"<>Excluded"))) -> 4 | X9: =IF(F9="","",N(G9)*N(I9)/(1-IF(K9="",'Job Info'!$B$39,K9))*IF('Job Info'!$B$38="Yes",'Job Info'!$B$37,0)) -> 270
A10: =IF(F10="","",ROW()-5) | M10: =IF(F10="","",N(I10)/(1-IF(K10="",'Job Info'!$B$39,K10))*(1+IF('Job Info'!$B$38="Yes",'Job Info'!$B$37,0))) | N10: =IF(F10="","",N(J10)/(1-IF(L10="",'Job Info'!$B$40,L10))) | O10: =IF(F10="","",M10+N10) | P10: =IF(F10="","",N(G10)*M10) | Q10: =IF(F10="","",N(G10)*N10) | R10: =IF(F10="","",P10+Q10) | U10: =IF(F10="","",N(G10)*N(I10)) | V10: =IF(F10="","",N(G10)*N(J10)) | W10: =IF(F10="","",IF(B10="Excluded","",COUNTIFS($F$6:F10,"?*",$B$6:B10,"<>Excluded"))) | X10: =IF(F10="","",N(G10)*N(I10)/(1-IF(K10="",'Job Info'!$B$39,K10))*IF('Job Info'!$B$38="Yes",'Job Info'!$B$37,0))
A11: =IF(F11="","",ROW()-5) | M11: =IF(F11="","",N(I11)/(1-IF(K11="",'Job Info'!$B$39,K11))*(1+IF('Job Info'!$B$38="Yes",'Job Info'!$B$37,0))) | N11: =IF(F11="","",N(J11)/(1-IF(L11="",'Job Info'!$B$40,L11))) | O11: =IF(F11="","",M11+N11) | P11: =IF(F11="","",N(G11)*M11) | Q11: =IF(F11="","",N(G11)*N11) | R11: =IF(F11="","",P11+Q11) | U11: =IF(F11="","",N(G11)*N(I11)) | V11: =IF(F11="","",N(G11)*N(J11)) | W11: =IF(F11="","",IF(B11="Excluded","",COUNTIFS($F$6:F11,"?*",$B$6:B11,"<>Excluded"))) | X11: =IF(F11="","",N(G11)*N(I11)/(1-IF(K11="",'Job Info'!$B$39,K11))*IF('Job Info'!$B$38="Yes",'Job Info'!$B$37,0))
A12: =IF(F12="","",ROW()-5) | M12: =IF(F12="","",N(I12)/(1-IF(K12="",'Job Info'!$B$39,K12))*(1+IF('Job Info'!$B$38="Yes",'Job Info'!$B$37,0))) | N12: =IF(F12="","",N(J12)/(1-IF(L12="",'Job Info'!$B$40,L12))) | O12: =IF(F12="","",M12+N12) | P12: =IF(F12="","",N(G12)*M12) | Q12: =IF(F12="","",N(G12)*N12) | R12: =IF(F12="","",P12+Q12) | U12: =IF(F12="","",N(G12)*N(I12)) | V12: =IF(F12="","",N(G12)*N(J12)) | W12: =IF(F12="","",IF(B12="Excluded","",COUNTIFS($F$6:F12,"?*",$B$6:B12,"<>Excluded"))) | X12: =IF(F12="","",N(G12)*N(I12)/(1-IF(K12="",'Job Info'!$B$39,K12))*IF('Job Info'!$B$38="Yes",'Job Info'!$B$37,0))
A13: =IF(F13="","",ROW()-5) | M13: =IF(F13="","",N(I13)/(1-IF(K13="",'Job Info'!$B$39,K13))*(1+IF('Job Info'!$B$38="Yes",'Job Info'!$B$37,0))) | N13: =IF(F13="","",N(J13)/(1-IF(L13="",'Job Info'!$B$40,L13))) | O13: =IF(F13="","",M13+N13) | P13: =IF(F13="","",N(G13)*M13) | Q13: =IF(F13="","",N(G13)*N13) | R13: =IF(F13="","",P13+Q13) | U13: =IF(F13="","",N(G13)*N(I13)) | V13: =IF(F13="","",N(G13)*N(J13)) | W13: =IF(F13="","",IF(B13="Excluded","",COUNTIFS($F$6:F13,"?*",$B$6:B13,"<>Excluded"))) | X13: =IF(F13="","",N(G13)*N(I13)/(1-IF(K13="",'Job Info'!$B$39,K13))*IF('Job Info'!$B$38="Yes",'Job Info'!$B$37,0))
A14: =IF(F14="","",ROW()-5) | M14: =IF(F14="","",N(I14)/(1-IF(K14="",'Job Info'!$B$39,K14))*(1+IF('Job Info'!$B$38="Yes",'Job Info'!$B$37,0))) | N14: =IF(F14="","",N(J14)/(1-IF(L14="",'Job Info'!$B$40,L14))) | O14: =IF(F14="","",M14+N14) | P14: =IF(F14="","",N(G14)*M14) | Q14: =IF(F14="","",N(G14)*N14) | R14: =IF(F14="","",P14+Q14) | U14: =IF(F14="","",N(G14)*N(I14)) | V14: =IF(F14="","",N(G14)*N(J14)) | W14: =IF(F14="","",IF(B14="Excluded","",COUNTIFS($F$6:F14,"?*",$B$6:B14,"<>Excluded"))) | X14: =IF(F14="","",N(G14)*N(I14)/(1-IF(K14="",'Job Info'!$B$39,K14))*IF('Job Info'!$B$38="Yes",'Job Info'!$B$37,0))
A15: =IF(F15="","",ROW()-5) | M15: =IF(F15="","",N(I15)/(1-IF(K15="",'Job Info'!$B$39,K15))*(1+IF('Job Info'!$B$38="Yes",'Job Info'!$B$37,0))) | N15: =IF(F15="","",N(J15)/(1-IF(L15="",'Job Info'!$B$40,L15))) | O15: =IF(F15="","",M15+N15) | P15: =IF(F15="","",N(G15)*M15) | Q15: =IF(F15="","",N(G15)*N15) | R15: =IF(F15="","",P15+Q15) | U15: =IF(F15="","",N(G15)*N(I15)) | V15: =IF(F15="","",N(G15)*N(J15)) | W15: =IF(F15="","",IF(B15="Excluded","",COUNTIFS($F$6:F15,"?*",$B$6:B15,"<>Excluded"))) | X15: =IF(F15="","",N(G15)*N(I15)/(1-IF(K15="",'Job Info'!$B$39,K15))*IF('Job Info'!$B$38="Yes",'Job Info'!$B$37,0))
A16: =IF(F16="","",ROW()-5) | M16: =IF(F16="","",N(I16)/(1-IF(K16="",'Job Info'!$B$39,K16))*(1+IF('Job Info'!$B$38="Yes",'Job Info'!$B$37,0))) | N16: =IF(F16="","",N(J16)/(1-IF(L16="",'Job Info'!$B$40,L16))) | O16: =IF(F16="","",M16+N16) | P16: =IF(F16="","",N(G16)*M16) | Q16: =IF(F16="","",N(G16)*N16) | R16: =IF(F16="","",P16+Q16) | U16: =IF(F16="","",N(G16)*N(I16)) | V16: =IF(F16="","",N(G16)*N(J16)) | W16: =IF(F16="","",IF(B16="Excluded","",COUNTIFS($F$6:F16,"?*",$B$6:B16,"<>Excluded"))) | X16: =IF(F16="","",N(G16)*N(I16)/(1-IF(K16="",'Job Info'!$B$39,K16))*IF('Job Info'!$B$38="Yes",'Job Info'!$B$37,0))
A17: =IF(F17="","",ROW()-5) | M17: =IF(F17="","",N(I17)/(1-IF(K17="",'Job Info'!$B$39,K17))*(1+IF('Job Info'!$B$38="Yes",'Job Info'!$B$37,0))) | N17: =IF(F17="","",N(J17)/(1-IF(L17="",'Job Info'!$B$40,L17))) | O17: =IF(F17="","",M17+N17) | P17: =IF(F17="","",N(G17)*M17) | Q17: =IF(F17="","",N(G17)*N17) | R17: =IF(F17="","",P17+Q17) | U17: =IF(F17="","",N(G17)*N(I17)) | V17: =IF(F17="","",N(G17)*N(J17)) | W17: =IF(F17="","",IF(B17="Excluded","",COUNTIFS($F$6:F17,"?*",$B$6:B17,"<>Excluded"))) | X17: =IF(F17="","",N(G17)*N(I17)/(1-IF(K17="",'Job Info'!$B$39,K17))*IF('Job Info'!$B$38="Yes",'Job Info'!$B$37,0))
A18: =IF(F18="","",ROW()-5) | M18: =IF(F18="","",N(I18)/(1-IF(K18="",'Job Info'!$B$39,K18))*(1+IF('Job Info'!$B$38="Yes",'Job Info'!$B$37,0))) | N18: =IF(F18="","",N(J18)/(1-IF(L18="",'Job Info'!$B$40,L18))) | O18: =IF(F18="","",M18+N18) | P18: =IF(F18="","",N(G18)*M18) | Q18: =IF(F18="","",N(G18)*N18) | R18: =IF(F18="","",P18+Q18) | U18: =IF(F18="","",N(G18)*N(I18)) | V18: =IF(F18="","",N(G18)*N(J18)) | W18: =IF(F18="","",IF(B18="Excluded","",COUNTIFS($F$6:F18,"?*",$B$6:B18,"<>Excluded"))) | X18: =IF(F18="","",N(G18)*N(I18)/(1-IF(K18="",'Job Info'!$B$39,K18))*IF('Job Info'!$B$38="Yes",'Job Info'!$B$37,0))
A19: =IF(F19="","",ROW()-5) | M19: =IF(F19="","",N(I19)/(1-IF(K19="",'Job Info'!$B$39,K19))*(1+IF('Job Info'!$B$38="Yes",'Job Info'!$B$37,0))) | N19: =IF(F19="","",N(J19)/(1-IF(L19="",'Job Info'!$B$40,L19))) | O19: =IF(F19="","",M19+N19) | P19: =IF(F19="","",N(G19)*M19) | Q19: =IF(F19="","",N(G19)*N19) | R19: =IF(F19="","",P19+Q19) | U19: =IF(F19="","",N(G19)*N(I19)) | V19: =IF(F19="","",N(G19)*N(J19)) | W19: =IF(F19="","",IF(B19="Excluded","",COUNTIFS($F$6:F19,"?*",$B$6:B19,"<>Excluded"))) | X19: =IF(F19="","",N(G19)*N(I19)/(1-IF(K19="",'Job Info'!$B$39,K19))*IF('Job Info'!$B$38="Yes",'Job Info'!$B$37,0))
A20: =IF(F20="","",ROW()-5) | M20: =IF(F20="","",N(I20)/(1-IF(K20="",'Job Info'!$B$39,K20))*(1+IF('Job Info'!$B$38="Yes",'Job Info'!$B$37,0))) | N20: =IF(F20="","",N(J20)/(1-IF(L20="",'Job Info'!$B$40,L20))) | O20: =IF(F20="","",M20+N20) | P20: =IF(F20="","",N(G20)*M20) | Q20: =IF(F20="","",N(G20)*N20) | R20: =IF(F20="","",P20+Q20) | U20: =IF(F20="","",N(G20)*N(I20)) | V20: =IF(F20="","",N(G20)*N(J20)) | W20: =IF(F20="","",IF(B20="Excluded","",COUNTIFS($F$6:F20,"?*",$B$6:B20,"<>Excluded"))) | X20: =IF(F20="","",N(G20)*N(I20)/(1-IF(K20="",'Job Info'!$B$39,K20))*IF('Job Info'!$B$38="Yes",'Job Info'!$B$37,0))
A21: =IF(F21="","",ROW()-5) | M21: =IF(F21="","",N(I21)/(1-IF(K21="",'Job Info'!$B$39,K21))*(1+IF('Job Info'!$B$38="Yes",'Job Info'!$B$37,0))) | N21: =IF(F21="","",N(J21)/(1-IF(L21="",'Job Info'!$B$40,L21))) | O21: =IF(F21="","",M21+N21) | P21: =IF(F21="","",N(G21)*M21) | Q21: =IF(F21="","",N(G21)*N21) | R21: =IF(F21="","",P21+Q21) | U21: =IF(F21="","",N(G21)*N(I21)) | V21: =IF(F21="","",N(G21)*N(J21)) | W21: =IF(F21="","",IF(B21="Excluded","",COUNTIFS($F$6:F21,"?*",$B$6:B21,"<>Excluded"))) | X21: =IF(F21="","",N(G21)*N(I21)/(1-IF(K21="",'Job Info'!$B$39,K21))*IF('Job Info'!$B$38="Yes",'Job Info'!$B$37,0))
... A505: =IF(F505="","",ROW()-5) | M505: =IF(F505="","",N(I505)/(1-IF(K505="",'Job Info'!$B$39,K505))*(1+IF('Job Info'!$B$38="Yes",'Job Info'!$B$37,0))) | N505: =IF(F505="","",N(J505)/(1-IF(L505="",'Job Info'!$B$40,L505))) | O505: =IF(F505="","",M505+N505) | P505: =IF(F505="","",N(G505)*M505) | Q505: =IF(F505="","",N(G505)*N505) | R505: =IF(F505="","",P505+Q505) | U505: =IF(F505="","",N(G505)*N(I505)) | V505: =IF(F505="","",N(G505)*N(J505)) | W505: =IF(F505="","",IF(B505="Excluded","",COUNTIFS($F$6:F505,"?*",$B$6:B505,"<>Excluded"))) | X505: =IF(F505="","",N(G505)*N(I505)/(1-IF(K505="",'Job Info'!$B$39,K505))*IF('Job Info'!$B$38="Yes",'Job Info'!$B$37,0))
F506: TOTAL - BASE BID LINES | P506: =SUMIFS(P6:P505,$B$6:$B$505,"Base") -> 4475.8125 | Q506: =SUMIFS(Q6:Q505,$B$6:$B$505,"Base") -> 1852.9412 | R506: =SUMIFS(R6:R505,$B$6:$B$505,"Base") -> 6328.7537 | U506: =SUMIFS(U6:U505,$B$6:$B$505,"Base") -> 3285 | V506: =SUMIFS(V6:V505,$B$6:$B$505,"Base") -> 1575

Sheet Alternates
A1: ALTERNATES & OPTIONS
A2: Alternate amounts total automatically from Line Detail lines tagged Alt 1-Alt 5. Enter deducts as negative quantities. Describe each alternate in column B; it only prints if it has a description or an amount.
A4: Alt # | B4: Description (prints on proposal) | C4: Add / (Deduct) | D4: Material | E4: Labor
A5: Alt 1 | B5: Battery-powered keypad deadbolts at unit entries in lieu of keyed deadbolts (EXAMPLE) | C5: =SUMIFS('Line Detail'!$R$6:$R$505,'Line Detail'!$B$6:$B$505,A5) -> 3564.1176 | D5: =SUMIFS('Line Detail'!$P$6:$P$505,'Line Detail'!$B$6:$B$505,A5) -> 3270 | E5: =SUMIFS('Line Detail'!$Q$6:$Q$505,'Line Detail'!$B$6:$B$505,A5) -> 294.11765
A6: Alt 2 | C6: =SUMIFS('Line Detail'!$R$6:$R$505,'Line Detail'!$B$6:$B$505,A6) -> 0 | D6: =SUMIFS('Line Detail'!$P$6:$P$505,'Line Detail'!$B$6:$B$505,A6) -> 0 | E6: =SUMIFS('Line Detail'!$Q$6:$Q$505,'Line Detail'!$B$6:$B$505,A6) -> 0
A7: Alt 3 | C7: =SUMIFS('Line Detail'!$R$6:$R$505,'Line Detail'!$B$6:$B$505,A7) -> 0 | D7: =SUMIFS('Line Detail'!$P$6:$P$505,'Line Detail'!$B$6:$B$505,A7) -> 0 | E7: =SUMIFS('Line Detail'!$Q$6:$Q$505,'Line Detail'!$B$6:$B$505,A7) -> 0
A8: Alt 4 | C8: =SUMIFS('Line Detail'!$R$6:$R$505,'Line Detail'!$B$6:$B$505,A8) -> 0 | D8: =SUMIFS('Line Detail'!$P$6:$P$505,'Line Detail'!$B$6:$B$505,A8) -> 0 | E8: =SUMIFS('Line Detail'!$Q$6:$Q$505,'Line Detail'!$B$6:$B$505,A8) -> 0
A9: Alt 5 | C9: =SUMIFS('Line Detail'!$R$6:$R$505,'Line Detail'!$B$6:$B$505,A9) -> 0 | D9: =SUMIFS('Line Detail'!$P$6:$P$505,'Line Detail'!$B$6:$B$505,A9) -> 0 | E9: =SUMIFS('Line Detail'!$Q$6:$Q$505,'Line Detail'!$B$6:$B$505,A9) -> 0
A11: Optional | B11: Optional items, priced individually in the attached Bid Summary | C11: =SUMIFS('Line Detail'!$R$6:$R$505,'Line Detail'!$B$6:$B$505,"Optional") -> 0 | D11: =SUMIFS('Line Detail'!$P$6:$P$505,'Line Detail'!$B$6:$B$505,"Optional") -> 0 | E11: =SUMIFS('Line Detail'!$Q$6:$Q$505,'Line Detail'!$B$6:$B$505,"Optional") -> 0

Sheet Scope Terms
A1: INCLUSIONS / EXCLUSIONS / QUALIFICATIONS / TERMS
A2: Set column B to Yes/No per job. 'Yes' items print on the Proposal, auto-numbered. Edit wording freely; add your own items in the blank rows at the end of each group (set the Category).
A3: Items in green are formulas that pull from Job Info - overwrite them only if you need custom wording.
A4: Category | B4: Print? | C4: Text | D4: Seq | E4: Key
A5: Inclusion | B5: Yes | C5: All items listed in the attached Bid Summary, which is part of this proposal. | D5: =IF(AND(B5="Yes",LEN(C5)>0),COUNTIFS($A$5:A5,A5,$B$5:B5,"Yes",$C$5:C5,"?*"),"") -> 1 | E5: =IF(D5="","",A5&"|"&D5) -> Inclusion|1
A6: Inclusion | B6: Yes | C6: =IF('Job Info'!$B$38="Yes","All material pricing includes "&TEXT('Job Info'!$B$37,"0.0%")&" sales tax.","Sales tax is NOT included in material pricing and will be added at invoicing.") -> All material pricing includes 9.0% sales tax. | D6: =IF(AND(B6="Yes",LEN(C6)>0),COUNTIFS($A$5:A6,A6,$B$5:B6,"Yes",$C$5:C6,"?*"),"") -> 2 | E6: =IF(D6="","",A6&"|"&D6) -> Inclusion|2
A7: Inclusion | B7: Yes | C7: ="Pricing is based on plans and specifications dated "&IF('Job Info'!$B$25="","[date TBD]",TEXT('Job Info'!$B$25,"mmmm d, yyyy"))&", and addenda: "&'Job Info'!$B$26&"." -> Pricing is based on plans and specifications dated [date TBD], and addenda: None. | D7: =IF(AND(B7="Yes",LEN(C7)>0),COUNTIFS($A$5:A7,A7,$B$5:B7,"Yes",$C$5:C7,"?*"),"") -> 3 | E7: =IF(D7="","",A7&"|"&D7) -> Inclusion|3
A8: Inclusion | B8: Yes | C8: Delivery of all materials to the jobsite, ground level, at each building. | D8: =IF(AND(B8="Yes",LEN(C8)>0),COUNTIFS($A$5:A8,A8,$B$5:B8,"Yes",$C$5:C8,"?*"),"") -> 4 | E8: =IF(D8="","",A8&"|"&D8) -> Inclusion|4
A9: Inclusion | B9: Yes | C9: Installation labor for every line item that shows a labor price in the Bid Summary. | D9: =IF(AND(B9="Yes",LEN(C9)>0),COUNTIFS($A$5:A9,A9,$B$5:B9,"Yes",$C$5:C9,"?*"),"") -> 5 | E9: =IF(D9="","",A9&"|"&D9) -> Inclusion|5
A10: Inclusion | B10: Yes | C10: Interior and exterior pre-hung doors with hinges installed and bored or prepped for the scheduled hardware. | D10: =IF(AND(B10="Yes",LEN(C10)>0),COUNTIFS($A$5:A10,A10,$B$5:B10,"Yes",$C$5:C10,"?*"),"") -> 6 | E10: =IF(D10="","",A10&"|"&D10) -> Inclusion|6
A11: Inclusion | B11: Yes | C11: Fire-rated doors and frames with factory labels as scheduled. | D11: =IF(AND(B11="Yes",LEN(C11)>0),COUNTIFS($A$5:A11,A11,$B$5:B11,"Yes",$C$5:C11,"?*"),"") -> 7 | E11: =IF(D11="","",A11&"|"&D11) -> Inclusion|7
A12: Inclusion | B12: Yes | C12: Product data, door and hardware schedules, and submittals; warranty and O&M documents at closeout. | D12: =IF(AND(B12="Yes",LEN(C12)>0),COUNTIFS($A$5:A12,A12,$B$5:B12,"Yes",$C$5:C12,"?*"),"") -> 8 | E12: =IF(D12="","",A12&"|"&D12) -> Inclusion|8
A13: Inclusion | B13: Yes | C13: Removal of our packaging and debris to the GC-provided on-site dumpster. | D13: =IF(AND(B13="Yes",LEN(C13)>0),COUNTIFS($A$5:A13,A13,$B$5:B13,"Yes",$C$5:C13,"?*"),"") -> 9 | E13: =IF(D13="","",A13&"|"&D13) -> Inclusion|9
A14: Inclusion | B14: No | D14: =IF(AND(B14="Yes",LEN(C14)>0),COUNTIFS($A$5:A14,A14,$B$5:B14,"Yes",$C$5:C14,"?*"),"") | E14: =IF(D14="","",A14&"|"&D14)
A15: Inclusion | B15: No | D15: =IF(AND(B15="Yes",LEN(C15)>0),COUNTIFS($A$5:A15,A15,$B$5:B15,"Yes",$C$5:C15,"?*"),"") | E15: =IF(D15="","",A15&"|"&D15)
A16: Inclusion | B16: No | D16: =IF(AND(B16="Yes",LEN(C16)>0),COUNTIFS($A$5:A16,A16,$B$5:B16,"Yes",$C$5:C16,"?*"),"") | E16: =IF(D16="","",A16&"|"&D16)
A17: Inclusion | B17: No | D17: =IF(AND(B17="Yes",LEN(C17)>0),COUNTIFS($A$5:A17,A17,$B$5:B17,"Yes",$C$5:C17,"?*"),"") | E17: =IF(D17="","",A17&"|"&D17)
A18: Exclusion | B18: Yes | C18: Chair rail and crown moulding in units | D18: =IF(AND(B18="Yes",LEN(C18)>0),COUNTIFS($A$5:A18,A18,$B$5:B18,"Yes",$C$5:C18,"?*"),"") -> 1 | E18: =IF(D18="","",A18&"|"&D18) -> Exclusion|1
A19: Exclusion | B19: Yes | C19: Cased openings and interior columns | D19: =IF(AND(B19="Yes",LEN(C19)>0),COUNTIFS($A$5:A19,A19,$B$5:B19,"Yes",$C$5:C19,"?*"),"") -> 2 | E19: =IF(D19="","",A19&"|"&D19) -> Exclusion|2
A20: Exclusion | B20: Yes | C20: Cabinets, countertops, vanities, desks, and built-ins unless listed | D20: =IF(AND(B20="Yes",LEN(C20)>0),COUNTIFS($A$5:A20,A20,$B$5:B20,"Yes",$C$5:C20,"?*"),"") -> 3 | E20: =IF(D20="","",A20&"|"&D20) -> Exclusion|3
A21: Exclusion | B21: Yes | C21: Stair parts and railings | D21: =IF(AND(B21="Yes",LEN(C21)>0),COUNTIFS($A$5:A21,A21,$B$5:B21,"Yes",$C$5:C21,"?*"),"") -> 4 | E21: =IF(D21="","",A21&"|"&D21) -> Exclusion|4
A22: Exclusion | B22: Yes | C22: Toilet partitions, shower doors, and shower enclosures unless listed | D22: =IF(AND(B22="Yes",LEN(C22)>0),COUNTIFS($A$5:A22,A22,$B$5:B22,"Yes",$C$5:C22,"?*"),"") -> 5 | E22: =IF(D22="","",A22&"|"&D22) -> Exclusion|5
A23: Exclusion | B23: Yes | C23: Garage doors, overhead doors, and draft-stop or attic access doors | D23: =IF(AND(B23="Yes",LEN(C23)>0),COUNTIFS($A$5:A23,A23,$B$5:B23,"Yes",$C$5:C23,"?*"),"") -> 6 | E23: =IF(D23="","",A23&"|"&D23) -> Exclusion|6
A24: Exclusion | B24: Yes | C24: Aluminum storefront, curtain wall, and associated door hardware | D24: =IF(AND(B24="Yes",LEN(C24)>0),COUNTIFS($A$5:A24,A24,$B$5:B24,"Yes",$C$5:C24,"?*"),"") -> 7 | E24: =IF(D24="","",A24&"|"&D24) -> Exclusion|7
A25: Exclusion | B25: Yes | C25: Glass and glazing for hollow metal doors and frames unless listed | D25: =IF(AND(B25="Yes",LEN(C25)>0),COUNTIFS($A$5:A25,A25,$B$5:B25,"Yes",$C$5:C25,"?*"),"") -> 8 | E25: =IF(D25="","",A25&"|"&D25) -> Exclusion|8
A26: Exclusion | B26: Yes | C26: Flashing, sealants, and weatherproofing for windows and doors | D26: =IF(AND(B26="Yes",LEN(C26)>0),COUNTIFS($A$5:A26,A26,$B$5:B26,"Yes",$C$5:C26,"?*"),"") -> 9 | E26: =IF(D26="","",A26&"|"&D26) -> Exclusion|9
A27: Exclusion | B27: Yes | C27: Painting, staining, caulking, and nail-hole fill (trim and doors are primed or prefinished as noted) | D27: =IF(AND(B27="Yes",LEN(C27)>0),COUNTIFS($A$5:A27,A27,$B$5:B27,"Yes",$C$5:C27,"?*"),"") -> 10 | E27: =IF(D27="","",A27&"|"&D27) -> Exclusion|10
A28: Exclusion | B28: Yes | C28: Wood blocking, backing, and framing | D28: =IF(AND(B28="Yes",LEN(C28)>0),COUNTIFS($A$5:A28,A28,$B$5:B28,"Yes",$C$5:C28,"?*"),"") -> 11 | E28: =IF(D28="","",A28&"|"&D28) -> Exclusion|11
A29: Exclusion | B29: Yes | C29: Grouting of hollow metal frames (material and labor) | D29: =IF(AND(B29="Yes",LEN(C29)>0),COUNTIFS($A$5:A29,A29,$B$5:B29,"Yes",$C$5:C29,"?*"),"") -> 12 | E29: =IF(D29="","",A29&"|"&D29) -> Exclusion|12
... A37: Exclusion | B37: Yes | C37: OCIP / CCIP insurance programs and related costs | D37: =IF(AND(B37="Yes",LEN(C37)>0),COUNTIFS($A$5:A37,A37,$B$5:B37,"Yes",$C$5:C37,"?*"),"") -> 20 | E37: =IF(D37="","",A37&"|"&D37) -> Exclusion|20
A38: Exclusion | B38: Yes | C38: =IF('Job Info'!$B$41="Yes","Bonds other than the payment and performance bond shown in the Proposal Summary","Payment and performance bonds") -> Payment and performance bonds | D38: =IF(AND(B38="Yes",LEN(C38)>0),COUNTIFS($A$5:A38,A38,$B$5:B38,"Yes",$C$5:C38,"?*"),"") -> 21 | E38: =IF(D38="","",A38&"|"&D38) -> Exclusion|21
A39: Exclusion | B39: Yes | C39: Builder's risk insurance, permits, inspection fees, and testing | D39: =IF(AND(B39="Yes",LEN(C39)>0),COUNTIFS($A$5:A39,A39,$B$5:B39,"Yes",$C$5:C39,"?*"),"") -> 22 | E39: =IF(D39="","",A39&"|"&D39) -> Exclusion|22
A40: Exclusion | B40: Yes | C40: Liquidated and consequential damages | D40: =IF(AND(B40="Yes",LEN(C40)>0),COUNTIFS($A$5:A40,A40,$B$5:B40,"Yes",$C$5:C40,"?*"),"") -> 23 | E40: =IF(D40="","",A40&"|"&D40) -> Exclusion|23
A41: Exclusion | B41: Yes | C41: Prevailing wage / Davis-Bacon labor rates unless stated | D41: =IF(AND(B41="Yes",LEN(C41)>0),COUNTIFS($A$5:A41,A41,$B$5:B41,"Yes",$C$5:C41,"?*"),"") -> 24 | E41: =IF(D41="","",A41&"|"&D41) -> Exclusion|24
A42: Exclusion | B42: Yes | C42: Attic stock and overage material | D42: =IF(AND(B42="Yes",LEN(C42)>0),COUNTIFS($A$5:A42,A42,$B$5:B42,"Yes",$C$5:C42,"?*"),"") -> 25 | E42: =IF(D42="","",A42&"|"&D42) -> Exclusion|25
A43: Exclusion | B43: Yes | C43: Protection of installed work from damage by other trades | D43: =IF(AND(B43="Yes",LEN(C43)>0),COUNTIFS($A$5:A43,A43,$B$5:B43,"Yes",$C$5:C43,"?*"),"") -> 26 | E43: =IF(D43="","",A43&"|"&D43) -> Exclusion|26
A44: Exclusion | B44: Yes | C44: Engineering, delegated design, and sealed shop drawings | D44: =IF(AND(B44="Yes",LEN(C44)>0),COUNTIFS($A$5:A44,A44,$B$5:B44,"Yes",$C$5:C44,"?*"),"") -> 27 | E44: =IF(D44="","",A44&"|"&D44) -> Exclusion|27
A45: Exclusion | B45: No | C45: Window blinds and window treatments | D45: =IF(AND(B45="Yes",LEN(C45)>0),COUNTIFS($A$5:A45,A45,$B$5:B45,"Yes",$C$5:C45,"?*"),"") | E45: =IF(D45="","",A45&"|"&D45)
A46: Exclusion | B46: No | C46: Postal boxes and mail kiosks | D46: =IF(AND(B46="Yes",LEN(C46)>0),COUNTIFS($A$5:A46,A46,$B$5:B46,"Yes",$C$5:C46,"?*"),"") | E46: =IF(D46="","",A46&"|"&D46)
A47: Exclusion | B47: No | C47: Wire shelving | D47: =IF(AND(B47="Yes",LEN(C47)>0),COUNTIFS($A$5:A47,A47,$B$5:B47,"Yes",$C$5:C47,"?*"),"") | E47: =IF(D47="","",A47&"|"&D47)
...

Sheet Proposal
A1: ='Job Info'!$B$5 -> Four Corners Building Supply
A2: ='Job Info'!$B$6&" | "&'Job Info'!$B$7&" | "&'Job Info'!$B$8&" | "&'Job Info'!$B$9 -> 4349 Corporate Road | North Charleston, SC 29405 | (843) 970-3812 | www.buildfcbs.com
A5: PROPOSAL
A7: To: | B7: ='Job Info'!$B$12&"" | D7: Date: | E7: =IF('Job Info'!$B$27="","",'Job Info'!$B$27)
A8: Attn: | B8: ='Job Info'!$B$13&"" | D8: Proposal #: | E8: ='Job Info'!$B$28&IF('Job Info'!$B$29&""="0",""," Rev "&'Job Info'!$B$29)
A9: Address: | B9: ='Job Info'!$B$14&"" | D9: From: | E9: ='Job Info'!$B$32&""
B10: ='Job Info'!$B$15&"" | D10: Phone: | E10: ='Job Info'!$B$33&""
A11: Phone: | B11: ='Job Info'!$B$16&"" | D11: Email: | E11: ='Job Info'!$B$34&""
A13: JOB NAME | D13: JOB # | E13: JOB ADDRESS
A14: ='Job Info'!$B$20&"" | D14: ='Job Info'!$B$21&"" | E14: ='Job Info'!$B$22&IF('Job Info'!$B$23="","",", "&'Job Info'!$B$23)
A16: PROPOSAL SUMMARY (BY CSI SECTION) | F16: AMOUNT
B17: =IF(1<=Lists!$J$2,INDEX(Lists!$B$2:$B$26,MATCH(1,Lists!$D$2:$D$26,0)),IF(1=Lists!$J$2+1,"Subtotal",IF(1=Lists!$J$2+2,Lists!$J$6,IF(1=Lists!$J$2+3,"BASE BID TOTAL","")))) -> 06 20 00 Interior Trim / Finish Carpentry | F17: =IF(1<=Lists!$J$2,INDEX(Lists!$C$2:$C$26,MATCH(1,Lists!$D$2:$D$26,0)),IF(1=Lists!$J$2+1,Lists!$J$3,IF(1=Lists!$J$2+2,Lists!$J$4,IF(1=Lists!$J$2+3,Lists!$J$5,"")))) -> 3269.7426
B18: =IF(2<=Lists!$J$2,INDEX(Lists!$B$2:$B$26,MATCH(2,Lists!$D$2:$D$26,0)),IF(2=Lists!$J$2+1,"Subtotal",IF(2=Lists!$J$2+2,Lists!$J$6,IF(2=Lists!$J$2+3,"BASE BID TOTAL","")))) -> 08 17 43 Interior Pre-Hung Doors | F18: =IF(2<=Lists!$J$2,INDEX(Lists!$C$2:$C$26,MATCH(2,Lists!$D$2:$D$26,0)),IF(2=Lists!$J$2+1,Lists!$J$3,IF(2=Lists!$J$2+2,Lists!$J$4,IF(2=Lists!$J$2+3,Lists!$J$5,"")))) -> 2695.1838
B19: =IF(3<=Lists!$J$2,INDEX(Lists!$B$2:$B$26,MATCH(3,Lists!$D$2:$D$26,0)),IF(3=Lists!$J$2+1,"Subtotal",IF(3=Lists!$J$2+2,Lists!$J$6,IF(3=Lists!$J$2+3,"BASE BID TOTAL","")))) -> 08 71 00 Door Hardware | F19: =IF(3<=Lists!$J$2,INDEX(Lists!$C$2:$C$26,MATCH(3,Lists!$D$2:$D$26,0)),IF(3=Lists!$J$2+1,Lists!$J$3,IF(3=Lists!$J$2+2,Lists!$J$4,IF(3=Lists!$J$2+3,Lists!$J$5,"")))) -> 363.82721
B20: =IF(4<=Lists!$J$2,INDEX(Lists!$B$2:$B$26,MATCH(4,Lists!$D$2:$D$26,0)),IF(4=Lists!$J$2+1,"Subtotal",IF(4=Lists!$J$2+2,Lists!$J$6,IF(4=Lists!$J$2+3,"BASE BID TOTAL","")))) -> Subtotal | F20: =IF(4<=Lists!$J$2,INDEX(Lists!$C$2:$C$26,MATCH(4,Lists!$D$2:$D$26,0)),IF(4=Lists!$J$2+1,Lists!$J$3,IF(4=Lists!$J$2+2,Lists!$J$4,IF(4=Lists!$J$2+3,Lists!$J$5,"")))) -> 6328.7537
B21: =IF(5<=Lists!$J$2,INDEX(Lists!$B$2:$B$26,MATCH(5,Lists!$D$2:$D$26,0)),IF(5=Lists!$J$2+1,"Subtotal",IF(5=Lists!$J$2+2,Lists!$J$6,IF(5=Lists!$J$2+3,"BASE BID TOTAL","")))) -> Payment & Performance Bond - Not Included | F21: =IF(5<=Lists!$J$2,INDEX(Lists!$C$2:$C$26,MATCH(5,Lists!$D$2:$D$26,0)),IF(5=Lists!$J$2+1,Lists!$J$3,IF(5=Lists!$J$2+2,Lists!$J$4,IF(5=Lists!$J$2+3,Lists!$J$5,"")))) -> 0
B22: =IF(6<=Lists!$J$2,INDEX(Lists!$B$2:$B$26,MATCH(6,Lists!$D$2:$D$26,0)),IF(6=Lists!$J$2+1,"Subtotal",IF(6=Lists!$J$2+2,Lists!$J$6,IF(6=Lists!$J$2+3,"BASE BID TOTAL","")))) -> BASE BID TOTAL | F22: =IF(6<=Lists!$J$2,INDEX(Lists!$C$2:$C$26,MATCH(6,Lists!$D$2:$D$26,0)),IF(6=Lists!$J$2+1,Lists!$J$3,IF(6=Lists!$J$2+2,Lists!$J$4,IF(6=Lists!$J$2+3,Lists!$J$5,"")))) -> 6328.7537
B23: =IF(7<=Lists!$J$2,INDEX(Lists!$B$2:$B$26,MATCH(7,Lists!$D$2:$D$26,0)),IF(7=Lists!$J$2+1,"Subtotal",IF(7=Lists!$J$2+2,Lists!$J$6,IF(7=Lists!$J$2+3,"BASE BID TOTAL","")))) | F23: =IF(7<=Lists!$J$2,INDEX(Lists!$C$2:$C$26,MATCH(7,Lists!$D$2:$D$26,0)),IF(7=Lists!$J$2+1,Lists!$J$3,IF(7=Lists!$J$2+2,Lists!$J$4,IF(7=Lists!$J$2+3,Lists!$J$5,""))))
B24: =IF(8<=Lists!$J$2,INDEX(Lists!$B$2:$B$26,MATCH(8,Lists!$D$2:$D$26,0)),IF(8=Lists!$J$2+1,"Subtotal",IF(8=Lists!$J$2+2,Lists!$J$6,IF(8=Lists!$J$2+3,"BASE BID TOTAL","")))) | F24: =IF(8<=Lists!$J$2,INDEX(Lists!$C$2:$C$26,MATCH(8,Lists!$D$2:$D$26,0)),IF(8=Lists!$J$2+1,Lists!$J$3,IF(8=Lists!$J$2+2,Lists!$J$4,IF(8=Lists!$J$2+3,Lists!$J$5,""))))
B25: =IF(9<=Lists!$J$2,INDEX(Lists!$B$2:$B$26,MATCH(9,Lists!$D$2:$D$26,0)),IF(9=Lists!$J$2+1,"Subtotal",IF(9=Lists!$J$2+2,Lists!$J$6,IF(9=Lists!$J$2+3,"BASE BID TOTAL","")))) | F25: =IF(9<=Lists!$J$2,INDEX(Lists!$C$2:$C$26,MATCH(9,Lists!$D$2:$D$26,0)),IF(9=Lists!$J$2+1,Lists!$J$3,IF(9=Lists!$J$2+2,Lists!$J$4,IF(9=Lists!$J$2+3,Lists!$J$5,""))))
B26: =IF(10<=Lists!$J$2,INDEX(Lists!$B$2:$B$26,MATCH(10,Lists!$D$2:$D$26,0)),IF(10=Lists!$J$2+1,"Subtotal",IF(10=Lists!$J$2+2,Lists!$J$6,IF(10=Lists!$J$2+3,"BASE BID TOTAL","")))) | F26: =IF(10<=Lists!$J$2,INDEX(Lists!$C$2:$C$26,MATCH(10,Lists!$D$2:$D$26,0)),IF(10=Lists!$J$2+1,Lists!$J$3,IF(10=Lists!$J$2+2,Lists!$J$4,IF(10=Lists!$J$2+3,Lists!$J$5,""))))
B27: =IF(11<=Lists!$J$2,INDEX(Lists!$B$2:$B$26,MATCH(11,Lists!$D$2:$D$26,0)),IF(11=Lists!$J$2+1,"Subtotal",IF(11=Lists!$J$2+2,Lists!$J$6,IF(11=Lists!$J$2+3,"BASE BID TOTAL","")))) | F27: =IF(11<=Lists!$J$2,INDEX(Lists!$C$2:$C$26,MATCH(11,Lists!$D$2:$D$26,0)),IF(11=Lists!$J$2+1,Lists!$J$3,IF(11=Lists!$J$2+2,Lists!$J$4,IF(11=Lists!$J$2+3,Lists!$J$5,""))))
B28: =IF(12<=Lists!$J$2,INDEX(Lists!$B$2:$B$26,MATCH(12,Lists!$D$2:$D$26,0)),IF(12=Lists!$J$2+1,"Subtotal",IF(12=Lists!$J$2+2,Lists!$J$6,IF(12=Lists!$J$2+3,"BASE BID TOTAL","")))) | F28: =IF(12<=Lists!$J$2,INDEX(Lists!$C$2:$C$26,MATCH(12,Lists!$D$2:$D$26,0)),IF(12=Lists!$J$2+1,Lists!$J$3,IF(12=Lists!$J$2+2,Lists!$J$4,IF(12=Lists!$J$2+3,Lists!$J$5,""))))
B29: =IF(13<=Lists!$J$2,INDEX(Lists!$B$2:$B$26,MATCH(13,Lists!$D$2:$D$26,0)),IF(13=Lists!$J$2+1,"Subtotal",IF(13=Lists!$J$2+2,Lists!$J$6,IF(13=Lists!$J$2+3,"BASE BID TOTAL","")))) | F29: =IF(13<=Lists!$J$2,INDEX(Lists!$C$2:$C$26,MATCH(13,Lists!$D$2:$D$26,0)),IF(13=Lists!$J$2+1,Lists!$J$3,IF(13=Lists!$J$2+2,Lists!$J$4,IF(13=Lists!$J$2+3,Lists!$J$5,""))))
B30: =IF(14<=Lists!$J$2,INDEX(Lists!$B$2:$B$26,MATCH(14,Lists!$D$2:$D$26,0)),IF(14=Lists!$J$2+1,"Subtotal",IF(14=Lists!$J$2+2,Lists!$J$6,IF(14=Lists!$J$2+3,"BASE BID TOTAL","")))) | F30: =IF(14<=Lists!$J$2,INDEX(Lists!$C$2:$C$26,MATCH(14,Lists!$D$2:$D$26,0)),IF(14=Lists!$J$2+1,Lists!$J$3,IF(14=Lists!$J$2+2,Lists!$J$4,IF(14=Lists!$J$2+3,Lists!$J$5,""))))
B31: =IF(15<=Lists!$J$2,INDEX(Lists!$B$2:$B$26,MATCH(15,Lists!$D$2:$D$26,0)),IF(15=Lists!$J$2+1,"Subtotal",IF(15=Lists!$J$2+2,Lists!$J$6,IF(15=Lists!$J$2+3,"BASE BID TOTAL","")))) | F31: =IF(15<=Lists!$J$2,INDEX(Lists!$C$2:$C$26,MATCH(15,Lists!$D$2:$D$26,0)),IF(15=Lists!$J$2+1,Lists!$J$3,IF(15=Lists!$J$2+2,Lists!$J$4,IF(15=Lists!$J$2+3,Lists!$J$5,""))))
B32: =IF(16<=Lists!$J$2,INDEX(Lists!$B$2:$B$26,MATCH(16,Lists!$D$2:$D$26,0)),IF(16=Lists!$J$2+1,"Subtotal",IF(16=Lists!$J$2+2,Lists!$J$6,IF(16=Lists!$J$2+3,"BASE BID TOTAL","")))) | F32: =IF(16<=Lists!$J$2,INDEX(Lists!$C$2:$C$26,MATCH(16,Lists!$D$2:$D$26,0)),IF(16=Lists!$J$2+1,Lists!$J$3,IF(16=Lists!$J$2+2,Lists!$J$4,IF(16=Lists!$J$2+3,Lists!$J$5,""))))
B33: =IF(17<=Lists!$J$2,INDEX(Lists!$B$2:$B$26,MATCH(17,Lists!$D$2:$D$26,0)),IF(17=Lists!$J$2+1,"Subtotal",IF(17=Lists!$J$2+2,Lists!$J$6,IF(17=Lists!$J$2+3,"BASE BID TOTAL","")))) | F33: =IF(17<=Lists!$J$2,INDEX(Lists!$C$2:$C$26,MATCH(17,Lists!$D$2:$D$26,0)),IF(17=Lists!$J$2+1,Lists!$J$3,IF(17=Lists!$J$2+2,Lists!$J$4,IF(17=Lists!$J$2+3,Lists!$J$5,""))))
B34: =IF(18<=Lists!$J$2,INDEX(Lists!$B$2:$B$26,MATCH(18,Lists!$D$2:$D$26,0)),IF(18=Lists!$J$2+1,"Subtotal",IF(18=Lists!$J$2+2,Lists!$J$6,IF(18=Lists!$J$2+3,"BASE BID TOTAL","")))) | F34: =IF(18<=Lists!$J$2,INDEX(Lists!$C$2:$C$26,MATCH(18,Lists!$D$2:$D$26,0)),IF(18=Lists!$J$2+1,Lists!$J$3,IF(18=Lists!$J$2+2,Lists!$J$4,IF(18=Lists!$J$2+3,Lists!$J$5,""))))
B35: =IF(19<=Lists!$J$2,INDEX(Lists!$B$2:$B$26,MATCH(19,Lists!$D$2:$D$26,0)),IF(19=Lists!$J$2+1,"Subtotal",IF(19=Lists!$J$2+2,Lists!$J$6,IF(19=Lists!$J$2+3,"BASE BID TOTAL","")))) | F35: =IF(19<=Lists!$J$2,INDEX(Lists!$C$2:$C$26,MATCH(19,Lists!$D$2:$D$26,0)),IF(19=Lists!$J$2+1,Lists!$J$3,IF(19=Lists!$J$2+2,Lists!$J$4,IF(19=Lists!$J$2+3,Lists!$J$5,""))))
A38: ALTERNATES & OPTIONS (NOT INCLUDED IN BASE BID) | F38: ADD / (DEDUCT)
A39: =IF(OR(Alternates!$B$5<>"",Alternates!$C$5<>0),Alternates!$A$5,"") -> Alt 1 | B39: =IF(OR(Alternates!$B$5<>"",Alternates!$C$5<>0),Alternates!$B$5&"","") -> Battery-powered keypad deadbolts at unit entries in lieu of keyed deadbolts (EXAMPLE) | F39: =IF(OR(Alternates!$B$5<>"",Alternates!$C$5<>0),Alternates!$C$5,"") -> 3564.1176
A40: =IF(OR(Alternates!$B$6<>"",Alternates!$C$6<>0),Alternates!$A$6,"") | B40: =IF(OR(Alternates!$B$6<>"",Alternates!$C$6<>0),Alternates!$B$6&"","") | F40: =IF(OR(Alternates!$B$6<>"",Alternates!$C$6<>0),Alternates!$C$6,"")
A41: =IF(OR(Alternates!$B$7<>"",Alternates!$C$7<>0),Alternates!$A$7,"") | B41: =IF(OR(Alternates!$B$7<>"",Alternates!$C$7<>0),Alternates!$B$7&"","") | F41: =IF(OR(Alternates!$B$7<>"",Alternates!$C$7<>0),Alternates!$C$7,"")
A42: =IF(OR(Alternates!$B$8<>"",Alternates!$C$8<>0),Alternates!$A$8,"") | B42: =IF(OR(Alternates!$B$8<>"",Alternates!$C$8<>0),Alternates!$B$8&"","") | F42: =IF(OR(Alternates!$B$8<>"",Alternates!$C$8<>0),Alternates!$C$8,"")
A43: =IF(OR(Alternates!$B$9<>"",Alternates!$C$9<>0),Alternates!$A$9,"") | B43: =IF(OR(Alternates!$B$9<>"",Alternates!$C$9<>0),Alternates!$B$9&"","") | F43: =IF(OR(Alternates!$B$9<>"",Alternates!$C$9<>0),Alternates!$C$9,"")
A44: =IF(Alternates!$C$11<>0,Alternates!$A$11,"") | B44: =IF(Alternates!$C$11<>0,Alternates!$B$11&"","") | F44: =IF(Alternates!$C$11<>0,Alternates!$C$11,"")
A46: ='Job Info'!$B$5&" is pleased to present this proposal for "&IF('Job Info'!$B$20="","[Job Name]",'Job Info'!$B$20)&", based on plans and specifications dated "&IF('Job Info'!$B$25="","[date TBD]",TEXT('Job Info'!$B$25,"mmmm d, yyyy"))&", subject to the inclusions, exclusions, qualifications, and terms below. The attached Bid Summary is part of this proposal." -> Four Corners Building Supply is pleased to present this proposal for [Job Name], based on plans and specifications dated [date TBD], subject to the inclusions, exclusions, qualifications, and terms below. The attached Bid Summary is part of this proposal.
A48: INCLUSIONS
A49: =IF(ISNA(MATCH("Inclusion|1",'Scope Terms'!$E$5:$E$88,0)),"",1&".") -> 1. | B49: =IFERROR(INDEX('Scope Terms'!$C$5:$C$88,MATCH("Inclusion|1",'Scope Terms'!$E$5:$E$88,0)),"") -> All items listed in the attached Bid Summary, which is part of this proposal.
...

Sheet Area Breakout
A1: ='Job Info'!$B$5&" - AREA BREAKOUT" -> Four Corners Building Supply - AREA BREAKOUT
A2: ="Job: "&'Job Info'!$B$20&" | Proposal "&'Job Info'!$B$28&" | "&IF('Job Info'!$B$38="Yes",TEXT('Job Info'!$B$37,"0.0%")&" sales tax included in all material prices","Sales tax not included") -> Job: | Proposal | 9.0% sales tax included in all material prices
A3: Base bid only. This is a lump-sum bid, broken out for the GC's convenience.
A5: CSI SECTION | B5: =IF('Job Info'!$B$53="","",'Job Info'!$B$53) -> Units / Apartments | C5: =IF('Job Info'!$B$54="","",'Job Info'!$B$54) -> Clubhouse | D5: =IF('Job Info'!$B$55="","",'Job Info'!$B$55) -> Leasing / Amenity | E5: =IF('Job Info'!$B$56="","",'Job Info'!$B$56) -> Corridors / Common | F5: =IF('Job Info'!$B$57="","",'Job Info'!$B$57) -> Maintenance | G5: =IF('Job Info'!$B$58="","",'Job Info'!$B$58) -> Garages | H5: =IF('Job Info'!$B$59="","",'Job Info'!$B$59) -> Pool Cabana | I5: =IF('Job Info'!$B$60="","",'Job Info'!$B$60) | J5: Unassigned | K5: TOTAL
A6: =IFERROR(INDEX(Lists!$B$2:$B$26,MATCH(1,Lists!$D$2:$D$26,0)),"") -> 06 20 00 Interior Trim / Finish Carpentry | B6: =IF($A6="","",IF('Job Info'!$B$53="",0,SUMIFS('Line Detail'!$R$6:$R$505,'Line Detail'!$C$6:$C$505,$A6,'Line Detail'!$D$6:$D$505,'Job Info'!$B$53,'Line Detail'!$B$6:$B$505,"Base"))) -> 3269.7426 | C6: =IF($A6="","",IF('Job Info'!$B$54="",0,SUMIFS('Line Detail'!$R$6:$R$505,'Line Detail'!$C$6:$C$505,$A6,'Line Detail'!$D$6:$D$505,'Job Info'!$B$54,'Line Detail'!$B$6:$B$505,"Base"))) -> 0 | D6: =IF($A6="","",IF('Job Info'!$B$55="",0,SUMIFS('Line Detail'!$R$6:$R$505,'Line Detail'!$C$6:$C$505,$A6,'Line Detail'!$D$6:$D$505,'Job Info'!$B$55,'Line Detail'!$B$6:$B$505,"Base"))) -> 0 | E6: =IF($A6="","",IF('Job Info'!$B$56="",0,SUMIFS('Line Detail'!$R$6:$R$505,'Line Detail'!$C$6:$C$505,$A6,'Line Detail'!$D$6:$D$505,'Job Info'!$B$56,'Line Detail'!$B$6:$B$505,"Base"))) -> 0 | F6: =IF($A6="","",IF('Job Info'!$B$57="",0,SUMIFS('Line Detail'!$R$6:$R$505,'Line Detail'!$C$6:$C$505,$A6,'Line Detail'!$D$6:$D$505,'Job Info'!$B$57,'Line Detail'!$B$6:$B$505,"Base"))) -> 0 | G6: =IF($A6="","",IF('Job Info'!$B$58="",0,SUMIFS('Line Detail'!$R$6:$R$505,'Line Detail'!$C$6:$C$505,$A6,'Line Detail'!$D$6:$D$505,'Job Info'!$B$58,'Line Detail'!$B$6:$B$505,"Base"))) -> 0 | H6: =IF($A6="","",IF('Job Info'!$B$59="",0,SUMIFS('Line Detail'!$R$6:$R$505,'Line Detail'!$C$6:$C$505,$A6,'Line Detail'!$D$6:$D$505,'Job Info'!$B$59,'Line Detail'!$B$6:$B$505,"Base"))) -> 0 | I6: =IF($A6="","",IF('Job Info'!$B$60="",0,SUMIFS('Line Detail'!$R$6:$R$505,'Line Detail'!$C$6:$C$505,$A6,'Line Detail'!$D$6:$D$505,'Job Info'!$B$60,'Line Detail'!$B$6:$B$505,"Base"))) -> 0 | J6: =IF($A6="","",K6-SUM(B6:I6)) -> 0 | K6: =IFERROR(INDEX(Lists!$C$2:$C$26,MATCH(1,Lists!$D$2:$D$26,0)),"") -> 3269.7426
A7: =IFERROR(INDEX(Lists!$B$2:$B$26,MATCH(2,Lists!$D$2:$D$26,0)),"") -> 08 17 43 Interior Pre-Hung Doors | B7: =IF($A7="","",IF('Job Info'!$B$53="",0,SUMIFS('Line Detail'!$R$6:$R$505,'Line Detail'!$C$6:$C$505,$A7,'Line Detail'!$D$6:$D$505,'Job Info'!$B$53,'Line Detail'!$B$6:$B$505,"Base"))) -> 2695.1838 | C7: =IF($A7="","",IF('Job Info'!$B$54="",0,SUMIFS('Line Detail'!$R$6:$R$505,'Line Detail'!$C$6:$C$505,$A7,'Line Detail'!$D$6:$D$505,'Job Info'!$B$54,'Line Detail'!$B$6:$B$505,"Base"))) -> 0 | D7: =IF($A7="","",IF('Job Info'!$B$55="",0,SUMIFS('Line Detail'!$R$6:$R$505,'Line Detail'!$C$6:$C$505,$A7,'Line Detail'!$D$6:$D$505,'Job Info'!$B$55,'Line Detail'!$B$6:$B$505,"Base"))) -> 0 | E7: =IF($A7="","",IF('Job Info'!$B$56="",0,SUMIFS('Line Detail'!$R$6:$R$505,'Line Detail'!$C$6:$C$505,$A7,'Line Detail'!$D$6:$D$505,'Job Info'!$B$56,'Line Detail'!$B$6:$B$505,"Base"))) -> 0 | F7: =IF($A7="","",IF('Job Info'!$B$57="",0,SUMIFS('Line Detail'!$R$6:$R$505,'Line Detail'!$C$6:$C$505,$A7,'Line Detail'!$D$6:$D$505,'Job Info'!$B$57,'Line Detail'!$B$6:$B$505,"Base"))) -> 0 | G7: =IF($A7="","",IF('Job Info'!$B$58="",0,SUMIFS('Line Detail'!$R$6:$R$505,'Line Detail'!$C$6:$C$505,$A7,'Line Detail'!$D$6:$D$505,'Job Info'!$B$58,'Line Detail'!$B$6:$B$505,"Base"))) -> 0 | H7: =IF($A7="","",IF('Job Info'!$B$59="",0,SUMIFS('Line Detail'!$R$6:$R$505,'Line Detail'!$C$6:$C$505,$A7,'Line Detail'!$D$6:$D$505,'Job Info'!$B$59,'Line Detail'!$B$6:$B$505,"Base"))) -> 0 | I7: =IF($A7="","",IF('Job Info'!$B$60="",0,SUMIFS('Line Detail'!$R$6:$R$505,'Line Detail'!$C$6:$C$505,$A7,'Line Detail'!$D$6:$D$505,'Job Info'!$B$60,'Line Detail'!$B$6:$B$505,"Base"))) -> 0 | J7: =IF($A7="","",K7-SUM(B7:I7)) -> 0 | K7: =IFERROR(INDEX(Lists!$C$2:$C$26,MATCH(2,Lists!$D$2:$D$26,0)),"") -> 2695.1838
A8: =IFERROR(INDEX(Lists!$B$2:$B$26,MATCH(3,Lists!$D$2:$D$26,0)),"") -> 08 71 00 Door Hardware | B8: =IF($A8="","",IF('Job Info'!$B$53="",0,SUMIFS('Line Detail'!$R$6:$R$505,'Line Detail'!$C$6:$C$505,$A8,'Line Detail'!$D$6:$D$505,'Job Info'!$B$53,'Line Detail'!$B$6:$B$505,"Base"))) -> 363.82721 | C8: =IF($A8="","",IF('Job Info'!$B$54="",0,SUMIFS('Line Detail'!$R$6:$R$505,'Line Detail'!$C$6:$C$505,$A8,'Line Detail'!$D$6:$D$505,'Job Info'!$B$54,'Line Detail'!$B$6:$B$505,"Base"))) -> 0 | D8: =IF($A8="","",IF('Job Info'!$B$55="",0,SUMIFS('Line Detail'!$R$6:$R$505,'Line Detail'!$C$6:$C$505,$A8,'Line Detail'!$D$6:$D$505,'Job Info'!$B$55,'Line Detail'!$B$6:$B$505,"Base"))) -> 0 | E8: =IF($A8="","",IF('Job Info'!$B$56="",0,SUMIFS('Line Detail'!$R$6:$R$505,'Line Detail'!$C$6:$C$505,$A8,'Line Detail'!$D$6:$D$505,'Job Info'!$B$56,'Line Detail'!$B$6:$B$505,"Base"))) -> 0 | F8: =IF($A8="","",IF('Job Info'!$B$57="",0,SUMIFS('Line Detail'!$R$6:$R$505,'Line Detail'!$C$6:$C$505,$A8,'Line Detail'!$D$6:$D$505,'Job Info'!$B$57,'Line Detail'!$B$6:$B$505,"Base"))) -> 0 | G8: =IF($A8="","",IF('Job Info'!$B$58="",0,SUMIFS('Line Detail'!$R$6:$R$505,'Line Detail'!$C$6:$C$505,$A8,'Line Detail'!$D$6:$D$505,'Job Info'!$B$58,'Line Detail'!$B$6:$B$505,"Base"))) -> 0 | H8: =IF($A8="","",IF('Job Info'!$B$59="",0,SUMIFS('Line Detail'!$R$6:$R$505,'Line Detail'!$C$6:$C$505,$A8,'Line Detail'!$D$6:$D$505,'Job Info'!$B$59,'Line Detail'!$B$6:$B$505,"Base"))) -> 0 | I8: =IF($A8="","",IF('Job Info'!$B$60="",0,SUMIFS('Line Detail'!$R$6:$R$505,'Line Detail'!$C$6:$C$505,$A8,'Line Detail'!$D$6:$D$505,'Job Info'!$B$60,'Line Detail'!$B$6:$B$505,"Base"))) -> 0 | J8: =IF($A8="","",K8-SUM(B8:I8)) -> 0 | K8: =IFERROR(INDEX(Lists!$C$2:$C$26,MATCH(3,Lists!$D$2:$D$26,0)),"") -> 363.82721
A9: =IFERROR(INDEX(Lists!$B$2:$B$26,MATCH(4,Lists!$D$2:$D$26,0)),"") | B9: =IF($A9="","",IF('Job Info'!$B$53="",0,SUMIFS('Line Detail'!$R$6:$R$505,'Line Detail'!$C$6:$C$505,$A9,'Line Detail'!$D$6:$D$505,'Job Info'!$B$53,'Line Detail'!$B$6:$B$505,"Base"))) | C9: =IF($A9="","",IF('Job Info'!$B$54="",0,SUMIFS('Line Detail'!$R$6:$R$505,'Line Detail'!$C$6:$C$505,$A9,'Line Detail'!$D$6:$D$505,'Job Info'!$B$54,'Line Detail'!$B$6:$B$505,"Base"))) | D9: =IF($A9="","",IF('Job Info'!$B$55="",0,SUMIFS('Line Detail'!$R$6:$R$505,'Line Detail'!$C$6:$C$505,$A9,'Line Detail'!$D$6:$D$505,'Job Info'!$B$55,'Line Detail'!$B$6:$B$505,"Base"))) | E9: =IF($A9="","",IF('Job Info'!$B$56="",0,SUMIFS('Line Detail'!$R$6:$R$505,'Line Detail'!$C$6:$C$505,$A9,'Line Detail'!$D$6:$D$505,'Job Info'!$B$56,'Line Detail'!$B$6:$B$505,"Base"))) | F9: =IF($A9="","",IF('Job Info'!$B$57="",0,SUMIFS('Line Detail'!$R$6:$R$505,'Line Detail'!$C$6:$C$505,$A9,'Line Detail'!$D$6:$D$505,'Job Info'!$B$57,'Line Detail'!$B$6:$B$505,"Base"))) | G9: =IF($A9="","",IF('Job Info'!$B$58="",0,SUMIFS('Line Detail'!$R$6:$R$505,'Line Detail'!$C$6:$C$505,$A9,'Line Detail'!$D$6:$D$505,'Job Info'!$B$58,'Line Detail'!$B$6:$B$505,"Base"))) | H9: =IF($A9="","",IF('Job Info'!$B$59="",0,SUMIFS('Line Detail'!$R$6:$R$505,'Line Detail'!$C$6:$C$505,$A9,'Line Detail'!$D$6:$D$505,'Job Info'!$B$59,'Line Detail'!$B$6:$B$505,"Base"))) | I9: =IF($A9="","",IF('Job Info'!$B$60="",0,SUMIFS('Line Detail'!$R$6:$R$505,'Line Detail'!$C$6:$C$505,$A9,'Line Detail'!$D$6:$D$505,'Job Info'!$B$60,'Line Detail'!$B$6:$B$505,"Base"))) | J9: =IF($A9="","",K9-SUM(B9:I9)) | K9: =IFERROR(INDEX(Lists!$C$2:$C$26,MATCH(4,Lists!$D$2:$D$26,0)),"")
A10: =IFERROR(INDEX(Lists!$B$2:$B$26,MATCH(5,Lists!$D$2:$D$26,0)),"") | B10: =IF($A10="","",IF('Job Info'!$B$53="",0,SUMIFS('Line Detail'!$R$6:$R$505,'Line Detail'!$C$6:$C$505,$A10,'Line Detail'!$D$6:$D$505,'Job Info'!$B$53,'Line Detail'!$B$6:$B$505,"Base"))) | C10: =IF($A10="","",IF('Job Info'!$B$54="",0,SUMIFS('Line Detail'!$R$6:$R$505,'Line Detail'!$C$6:$C$505,$A10,'Line Detail'!$D$6:$D$505,'Job Info'!$B$54,'Line Detail'!$B$6:$B$505,"Base"))) | D10: =IF($A10="","",IF('Job Info'!$B$55="",0,SUMIFS('Line Detail'!$R$6:$R$505,'Line Detail'!$C$6:$C$505,$A10,'Line Detail'!$D$6:$D$505,'Job Info'!$B$55,'Line Detail'!$B$6:$B$505,"Base"))) | E10: =IF($A10="","",IF('Job Info'!$B$56="",0,SUMIFS('Line Detail'!$R$6:$R$505,'Line Detail'!$C$6:$C$505,$A10,'Line Detail'!$D$6:$D$505,'Job Info'!$B$56,'Line Detail'!$B$6:$B$505,"Base"))) | F10: =IF($A10="","",IF('Job Info'!$B$57="",0,SUMIFS('Line Detail'!$R$6:$R$505,'Line Detail'!$C$6:$C$505,$A10,'Line Detail'!$D$6:$D$505,'Job Info'!$B$57,'Line Detail'!$B$6:$B$505,"Base"))) | G10: =IF($A10="","",IF('Job Info'!$B$58="",0,SUMIFS('Line Detail'!$R$6:$R$505,'Line Detail'!$C$6:$C$505,$A10,'Line Detail'!$D$6:$D$505,'Job Info'!$B$58,'Line Detail'!$B$6:$B$505,"Base"))) | H10: =IF($A10="","",IF('Job Info'!$B$59="",0,SUMIFS('Line Detail'!$R$6:$R$505,'Line Detail'!$C$6:$C$505,$A10,'Line Detail'!$D$6:$D$505,'Job Info'!$B$59,'Line Detail'!$B$6:$B$505,"Base"))) | I10: =IF($A10="","",IF('Job Info'!$B$60="",0,SUMIFS('Line Detail'!$R$6:$R$505,'Line Detail'!$C$6:$C$505,$A10,'Line Detail'!$D$6:$D$505,'Job Info'!$B$60,'Line Detail'!$B$6:$B$505,"Base"))) | J10: =IF($A10="","",K10-SUM(B10:I10)) | K10: =IFERROR(INDEX(Lists!$C$2:$C$26,MATCH(5,Lists!$D$2:$D$26,0)),"")
A11: =IFERROR(INDEX(Lists!$B$2:$B$26,MATCH(6,Lists!$D$2:$D$26,0)),"") | B11: =IF($A11="","",IF('Job Info'!$B$53="",0,SUMIFS('Line Detail'!$R$6:$R$505,'Line Detail'!$C$6:$C$505,$A11,'Line Detail'!$D$6:$D$505,'Job Info'!$B$53,'Line Detail'!$B$6:$B$505,"Base"))) | C11: =IF($A11="","",IF('Job Info'!$B$54="",0,SUMIFS('Line Detail'!$R$6:$R$505,'Line Detail'!$C$6:$C$505,$A11,'Line Detail'!$D$6:$D$505,'Job Info'!$B$54,'Line Detail'!$B$6:$B$505,"Base"))) | D11: =IF($A11="","",IF('Job Info'!$B$55="",0,SUMIFS('Line Detail'!$R$6:$R$505,'Line Detail'!$C$6:$C$505,$A11,'Line Detail'!$D$6:$D$505,'Job Info'!$B$55,'Line Detail'!$B$6:$B$505,"Base"))) | E11: =IF($A11="","",IF('Job Info'!$B$56="",0,SUMIFS('Line Detail'!$R$6:$R$505,'Line Detail'!$C$6:$C$505,$A11,'Line Detail'!$D$6:$D$505,'Job Info'!$B$56,'Line Detail'!$B$6:$B$505,"Base"))) | F11: =IF($A11="","",IF('Job Info'!$B$57="",0,SUMIFS('Line Detail'!$R$6:$R$505,'Line Detail'!$C$6:$C$505,$A11,'Line Detail'!$D$6:$D$505,'Job Info'!$B$57,'Line Detail'!$B$6:$B$505,"Base"))) | G11: =IF($A11="","",IF('Job Info'!$B$58="",0,SUMIFS('Line Detail'!$R$6:$R$505,'Line Detail'!$C$6:$C$505,$A11,'Line Detail'!$D$6:$D$505,'Job Info'!$B$58,'Line Detail'!$B$6:$B$505,"Base"))) | H11: =IF($A11="","",IF('Job Info'!$B$59="",0,SUMIFS('Line Detail'!$R$6:$R$505,'Line Detail'!$C$6:$C$505,$A11,'Line Detail'!$D$6:$D$505,'Job Info'!$B$59,'Line Detail'!$B$6:$B$505,"Base"))) | I11: =IF($A11="","",IF('Job Info'!$B$60="",0,SUMIFS('Line Detail'!$R$6:$R$505,'Line Detail'!$C$6:$C$505,$A11,'Line Detail'!$D$6:$D$505,'Job Info'!$B$60,'Line Detail'!$B$6:$B$505,"Base"))) | J11: =IF($A11="","",K11-SUM(B11:I11)) | K11: =IFERROR(INDEX(Lists!$C$2:$C$26,MATCH(6,Lists!$D$2:$D$26,0)),"")
A12: =IFERROR(INDEX(Lists!$B$2:$B$26,MATCH(7,Lists!$D$2:$D$26,0)),"") | B12: =IF($A12="","",IF('Job Info'!$B$53="",0,SUMIFS('Line Detail'!$R$6:$R$505,'Line Detail'!$C$6:$C$505,$A12,'Line Detail'!$D$6:$D$505,'Job Info'!$B$53,'Line Detail'!$B$6:$B$505,"Base"))) | C12: =IF($A12="","",IF('Job Info'!$B$54="",0,SUMIFS('Line Detail'!$R$6:$R$505,'Line Detail'!$C$6:$C$505,$A12,'Line Detail'!$D$6:$D$505,'Job Info'!$B$54,'Line Detail'!$B$6:$B$505,"Base"))) | D12: =IF($A12="","",IF('Job Info'!$B$55="",0,SUMIFS('Line Detail'!$R$6:$R$505,'Line Detail'!$C$6:$C$505,$A12,'Line Detail'!$D$6:$D$505,'Job Info'!$B$55,'Line Detail'!$B$6:$B$505,"Base"))) | E12: =IF($A12="","",IF('Job Info'!$B$56="",0,SUMIFS('Line Detail'!$R$6:$R$505,'Line Detail'!$C$6:$C$505,$A12,'Line Detail'!$D$6:$D$505,'Job Info'!$B$56,'Line Detail'!$B$6:$B$505,"Base"))) | F12: =IF($A12="","",IF('Job Info'!$B$57="",0,SUMIFS('Line Detail'!$R$6:$R$505,'Line Detail'!$C$6:$C$505,$A12,'Line Detail'!$D$6:$D$505,'Job Info'!$B$57,'Line Detail'!$B$6:$B$505,"Base"))) | G12: =IF($A12="","",IF('Job Info'!$B$58="",0,SUMIFS('Line Detail'!$R$6:$R$505,'Line Detail'!$C$6:$C$505,$A12,'Line Detail'!$D$6:$D$505,'Job Info'!$B$58,'Line Detail'!$B$6:$B$505,"Base"))) | H12: =IF($A12="","",IF('Job Info'!$B$59="",0,SUMIFS('Line Detail'!$R$6:$R$505,'Line Detail'!$C$6:$C$505,$A12,'Line Detail'!$D$6:$D$505,'Job Info'!$B$59,'Line Detail'!$B$6:$B$505,"Base"))) | I12: =IF($A12="","",IF('Job Info'!$B$60="",0,SUMIFS('Line Detail'!$R$6:$R$505,'Line Detail'!$C$6:$C$505,$A12,'Line Detail'!$D$6:$D$505,'Job Info'!$B$60,'Line Detail'!$B$6:$B$505,"Base"))) | J12: =IF($A12="","",K12-SUM(B12:I12)) | K12: =IFERROR(INDEX(Lists!$C$2:$C$26,MATCH(7,Lists!$D$2:$D$26,0)),"")
A13: =IFERROR(INDEX(Lists!$B$2:$B$26,MATCH(8,Lists!$D$2:$D$26,0)),"") | B13: =IF($A13="","",IF('Job Info'!$B$53="",0,SUMIFS('Line Detail'!$R$6:$R$505,'Line Detail'!$C$6:$C$505,$A13,'Line Detail'!$D$6:$D$505,'Job Info'!$B$53,'Line Detail'!$B$6:$B$505,"Base"))) | C13: =IF($A13="","",IF('Job Info'!$B$54="",0,SUMIFS('Line Detail'!$R$6:$R$505,'Line Detail'!$C$6:$C$505,$A13,'Line Detail'!$D$6:$D$505,'Job Info'!$B$54,'Line Detail'!$B$6:$B$505,"Base"))) | D13: =IF($A13="","",IF('Job Info'!$B$55="",0,SUMIFS('Line Detail'!$R$6:$R$505,'Line Detail'!$C$6:$C$505,$A13,'Line Detail'!$D$6:$D$505,'Job Info'!$B$55,'Line Detail'!$B$6:$B$505,"Base"))) | E13: =IF($A13="","",IF('Job Info'!$B$56="",0,SUMIFS('Line Detail'!$R$6:$R$505,'Line Detail'!$C$6:$C$505,$A13,'Line Detail'!$D$6:$D$505,'Job Info'!$B$56,'Line Detail'!$B$6:$B$505,"Base"))) | F13: =IF($A13="","",IF('Job Info'!$B$57="",0,SUMIFS('Line Detail'!$R$6:$R$505,'Line Detail'!$C$6:$C$505,$A13,'Line Detail'!$D$6:$D$505,'Job Info'!$B$57,'Line Detail'!$B$6:$B$505,"Base"))) | G13: =IF($A13="","",IF('Job Info'!$B$58="",0,SUMIFS('Line Detail'!$R$6:$R$505,'Line Detail'!$C$6:$C$505,$A13,'Line Detail'!$D$6:$D$505,'Job Info'!$B$58,'Line Detail'!$B$6:$B$505,"Base"))) | H13: =IF($A13="","",IF('Job Info'!$B$59="",0,SUMIFS('Line Detail'!$R$6:$R$505,'Line Detail'!$C$6:$C$505,$A13,'Line Detail'!$D$6:$D$505,'Job Info'!$B$59,'Line Detail'!$B$6:$B$505,"Base"))) | I13: =IF($A13="","",IF('Job Info'!$B$60="",0,SUMIFS('Line Detail'!$R$6:$R$505,'Line Detail'!$C$6:$C$505,$A13,'Line Detail'!$D$6:$D$505,'Job Info'!$B$60,'Line Detail'!$B$6:$B$505,"Base"))) | J13: =IF($A13="","",K13-SUM(B13:I13)) | K13: =IFERROR(INDEX(Lists!$C$2:$C$26,MATCH(8,Lists!$D$2:$D$26,0)),"")
A14: =IFERROR(INDEX(Lists!$B$2:$B$26,MATCH(9,Lists!$D$2:$D$26,0)),"") | B14: =IF($A14="","",IF('Job Info'!$B$53="",0,SUMIFS('Line Detail'!$R$6:$R$505,'Line Detail'!$C$6:$C$505,$A14,'Line Detail'!$D$6:$D$505,'Job Info'!$B$53,'Line Detail'!$B$6:$B$505,"Base"))) | C14: =IF($A14="","",IF('Job Info'!$B$54="",0,SUMIFS('Line Detail'!$R$6:$R$505,'Line Detail'!$C$6:$C$505,$A14,'Line Detail'!$D$6:$D$505,'Job Info'!$B$54,'Line Detail'!$B$6:$B$505,"Base"))) | D14: =IF($A14="","",IF('Job Info'!$B$55="",0,SUMIFS('Line Detail'!$R$6:$R$505,'Line Detail'!$C$6:$C$505,$A14,'Line Detail'!$D$6:$D$505,'Job Info'!$B$55,'Line Detail'!$B$6:$B$505,"Base"))) | E14: =IF($A14="","",IF('Job Info'!$B$56="",0,SUMIFS('Line Detail'!$R$6:$R$505,'Line Detail'!$C$6:$C$505,$A14,'Line Detail'!$D$6:$D$505,'Job Info'!$B$56,'Line Detail'!$B$6:$B$505,"Base"))) | F14: =IF($A14="","",IF('Job Info'!$B$57="",0,SUMIFS('Line Detail'!$R$6:$R$505,'Line Detail'!$C$6:$C$505,$A14,'Line Detail'!$D$6:$D$505,'Job Info'!$B$57,'Line Detail'!$B$6:$B$505,"Base"))) | G14: =IF($A14="","",IF('Job Info'!$B$58="",0,SUMIFS('Line Detail'!$R$6:$R$505,'Line Detail'!$C$6:$C$505,$A14,'Line Detail'!$D$6:$D$505,'Job Info'!$B$58,'Line Detail'!$B$6:$B$505,"Base"))) | H14: =IF($A14="","",IF('Job Info'!$B$59="",0,SUMIFS('Line Detail'!$R$6:$R$505,'Line Detail'!$C$6:$C$505,$A14,'Line Detail'!$D$6:$D$505,'Job Info'!$B$59,'Line Detail'!$B$6:$B$505,"Base"))) | I14: =IF($A14="","",IF('Job Info'!$B$60="",0,SUMIFS('Line Detail'!$R$6:$R$505,'Line Detail'!$C$6:$C$505,$A14,'Line Detail'!$D$6:$D$505,'Job Info'!$B$60,'Line Detail'!$B$6:$B$505,"Base"))) | J14: =IF($A14="","",K14-SUM(B14:I14)) | K14: =IFERROR(INDEX(Lists!$C$2:$C$26,MATCH(9,Lists!$D$2:$D$26,0)),"")
A15: =IFERROR(INDEX(Lists!$B$2:$B$26,MATCH(10,Lists!$D$2:$D$26,0)),"") | B15: =IF($A15="","",IF('Job Info'!$B$53="",0,SUMIFS('Line Detail'!$R$6:$R$505,'Line Detail'!$C$6:$C$505,$A15,'Line Detail'!$D$6:$D$505,'Job Info'!$B$53,'Line Detail'!$B$6:$B$505,"Base"))) | C15: =IF($A15="","",IF('Job Info'!$B$54="",0,SUMIFS('Line Detail'!$R$6:$R$505,'Line Detail'!$C$6:$C$505,$A15,'Line Detail'!$D$6:$D$505,'Job Info'!$B$54,'Line Detail'!$B$6:$B$505,"Base"))) | D15: =IF($A15="","",IF('Job Info'!$B$55="",0,SUMIFS('Line Detail'!$R$6:$R$505,'Line Detail'!$C$6:$C$505,$A15,'Line Detail'!$D$6:$D$505,'Job Info'!$B$55,'Line Detail'!$B$6:$B$505,"Base"))) | E15: =IF($A15="","",IF('Job Info'!$B$56="",0,SUMIFS('Line Detail'!$R$6:$R$505,'Line Detail'!$C$6:$C$505,$A15,'Line Detail'!$D$6:$D$505,'Job Info'!$B$56,'Line Detail'!$B$6:$B$505,"Base"))) | F15: =IF($A15="","",IF('Job Info'!$B$57="",0,SUMIFS('Line Detail'!$R$6:$R$505,'Line Detail'!$C$6:$C$505,$A15,'Line Detail'!$D$6:$D$505,'Job Info'!$B$57,'Line Detail'!$B$6:$B$505,"Base"))) | G15: =IF($A15="","",IF('Job Info'!$B$58="",0,SUMIFS('Line Detail'!$R$6:$R$505,'Line Detail'!$C$6:$C$505,$A15,'Line Detail'!$D$6:$D$505,'Job Info'!$B$58,'Line Detail'!$B$6:$B$505,"Base"))) | H15: =IF($A15="","",IF('Job Info'!$B$59="",0,SUMIFS('Line Detail'!$R$6:$R$505,'Line Detail'!$C$6:$C$505,$A15,'Line Detail'!$D$6:$D$505,'Job Info'!$B$59,'Line Detail'!$B$6:$B$505,"Base"))) | I15: =IF($A15="","",IF('Job Info'!$B$60="",0,SUMIFS('Line Detail'!$R$6:$R$505,'Line Detail'!$C$6:$C$505,$A15,'Line Detail'!$D$6:$D$505,'Job Info'!$B$60,'Line Detail'!$B$6:$B$505,"Base"))) | J15: =IF($A15="","",K15-SUM(B15:I15)) | K15: =IFERROR(INDEX(Lists!$C$2:$C$26,MATCH(10,Lists!$D$2:$D$26,0)),"")
A16: =IFERROR(INDEX(Lists!$B$2:$B$26,MATCH(11,Lists!$D$2:$D$26,0)),"") | B16: =IF($A16="","",IF('Job Info'!$B$53="",0,SUMIFS('Line Detail'!$R$6:$R$505,'Line Detail'!$C$6:$C$505,$A16,'Line Detail'!$D$6:$D$505,'Job Info'!$B$53,'Line Detail'!$B$6:$B$505,"Base"))) | C16: =IF($A16="","",IF('Job Info'!$B$54="",0,SUMIFS('Line Detail'!$R$6:$R$505,'Line Detail'!$C$6:$C$505,$A16,'Line Detail'!$D$6:$D$505,'Job Info'!$B$54,'Line Detail'!$B$6:$B$505,"Base"))) | D16: =IF($A16="","",IF('Job Info'!$B$55="",0,SUMIFS('Line Detail'!$R$6:$R$505,'Line Detail'!$C$6:$C$505,$A16,'Line Detail'!$D$6:$D$505,'Job Info'!$B$55,'Line Detail'!$B$6:$B$505,"Base"))) | E16: =IF($A16="","",IF('Job Info'!$B$56="",0,SUMIFS('Line Detail'!$R$6:$R$505,'Line Detail'!$C$6:$C$505,$A16,'Line Detail'!$D$6:$D$505,'Job Info'!$B$56,'Line Detail'!$B$6:$B$505,"Base"))) | F16: =IF($A16="","",IF('Job Info'!$B$57="",0,SUMIFS('Line Detail'!$R$6:$R$505,'Line Detail'!$C$6:$C$505,$A16,'Line Detail'!$D$6:$D$505,'Job Info'!$B$57,'Line Detail'!$B$6:$B$505,"Base"))) | G16: =IF($A16="","",IF('Job Info'!$B$58="",0,SUMIFS('Line Detail'!$R$6:$R$505,'Line Detail'!$C$6:$C$505,$A16,'Line Detail'!$D$6:$D$505,'Job Info'!$B$58,'Line Detail'!$B$6:$B$505,"Base"))) | H16: =IF($A16="","",IF('Job Info'!$B$59="",0,SUMIFS('Line Detail'!$R$6:$R$505,'Line Detail'!$C$6:$C$505,$A16,'Line Detail'!$D$6:$D$505,'Job Info'!$B$59,'Line Detail'!$B$6:$B$505,"Base"))) | I16: =IF($A16="","",IF('Job Info'!$B$60="",0,SUMIFS('Line Detail'!$R$6:$R$505,'Line Detail'!$C$6:$C$505,$A16,'Line Detail'!$D$6:$D$505,'Job Info'!$B$60,'Line Detail'!$B$6:$B$505,"Base"))) | J16: =IF($A16="","",K16-SUM(B16:I16)) | K16: =IFERROR(INDEX(Lists!$C$2:$C$26,MATCH(11,Lists!$D$2:$D$26,0)),"")
